2025-09-18 01:13:20,390 - INFO - Bot: eom_master_inspector [@eom_master_inspectorbot]
2025-09-18 01:13:20,559 - WARNING - Updates were skipped successfully.
2025-09-18 01:13:20,823 - INFO - Start polling.
2025-09-18 01:15:16,437 - ERROR - Task exception was never retrieved
future: <Task finished name='Task-31' coro=<Dispatcher._process_polling_updates() done, defined at /root/tg_bot/Sharing/venv/lib/python3.11/site-packages/aiogram/dispatcher/dispatcher.py:407> exception=CantParseEntities('Can\'t parse entities: unsupported start tag "начало" at byte offset 40')>
Traceback (most recent call last):
  File "/root/tg_bot/Sharing/venv/lib/python3.11/site-packages/aiogram/dispatcher/dispatcher.py", line 415, in _process_polling_updates
    for responses in itertools.chain.from_iterable(await self.process_updates(updates, fast)):
                                                   ^^^^^^^^^^^^^^^^^^^^^^^^^^^^^^^^^^^^^^^^^
  File "/root/tg_bot/Sharing/venv/lib/python3.11/site-packages/aiogram/dispatcher/dispatcher.py", line 235, in process_updates
    return await asyncio.gather(*tasks)
           ^^^^^^^^^^^^^^^^^^^^^^^^^^^^
  File "/root/tg_bot/Sharing/venv/lib/python3.11/site-packages/aiogram/dispatcher/handler.py", line 117, in notify
    response = await handler_obj.handler(*args, **partial_data)
               ^^^^^^^^^^^^^^^^^^^^^^^^^^^^^^^^^^^^^^^^^^^^^^^^
  File "/root/tg_bot/Sharing/venv/lib/python3.11/site-packages/aiogram/dispatcher/dispatcher.py", line 256, in process_update
    return await self.message_handlers.notify(update.message)
           ^^^^^^^^^^^^^^^^^^^^^^^^^^^^^^^^^^^^^^^^^^^^^^^^^^
  File "/root/tg_bot/Sharing/venv/lib/python3.11/site-packages/aiogram/dispatcher/handler.py", line 117, in notify
    response = await handler_obj.handler(*args, **partial_data)
               ^^^^^^^^^^^^^^^^^^^^^^^^^^^^^^^^^^^^^^^^^^^^^^^^
  File "/root/tg_bot/Sharing/handlers.py", line 228, in service_report_handler
    await message.reply(
  File "/root/tg_bot/Sharing/venv/lib/python3.11/site-packages/aiogram/types/message.py", line 1687, in reply
    return await self.bot.send_message(
           ^^^^^^^^^^^^^^^^^^^^^^^^^^^^
  File "/root/tg_bot/Sharing/venv/lib/python3.11/site-packages/aiogram/bot/bot.py", line 346, in send_message
    result = await self.request(api.Methods.SEND_MESSAGE, payload)
             ^^^^^^^^^^^^^^^^^^^^^^^^^^^^^^^^^^^^^^^^^^^^^^^^^^^^^
  File "/root/tg_bot/Sharing/venv/lib/python3.11/site-packages/aiogram/bot/base.py", line 236, in request
    return await api.make_request(await self.get_session(), self.server, self.__token, method, data, files,
           ^^^^^^^^^^^^^^^^^^^^^^^^^^^^^^^^^^^^^^^^^^^^^^^^^^^^^^^^^^^^^^^^^^^^^^^^^^^^^^^^^^^^^^^^^^^^^^^^
  File "/root/tg_bot/Sharing/venv/lib/python3.11/site-packages/aiogram/bot/api.py", line 140, in make_request
    return check_result(method, response.content_type, response.status, await response.text())
           ^^^^^^^^^^^^^^^^^^^^^^^^^^^^^^^^^^^^^^^^^^^^^^^^^^^^^^^^^^^^^^^^^^^^^^^^^^^^^^^^^^^
  File "/root/tg_bot/Sharing/venv/lib/python3.11/site-packages/aiogram/bot/api.py", line 115, in check_result
    exceptions.BadRequest.detect(description)
  File "/root/tg_bot/Sharing/venv/lib/python3.11/site-packages/aiogram/utils/exceptions.py", line 140, in detect
    raise err(cls.text or description)
aiogram.utils.exceptions.CantParseEntities: Can't parse entities: unsupported start tag "начало" at byte offset 40
2025-09-18 03:03:22,041 - ERROR - Cause exception while getting updates.
Traceback (most recent call last):
  File "/root/tg_bot/Sharing/venv/lib/python3.11/site-packages/aiogram/bot/api.py", line 139, in make_request
    async with session.post(url, data=req, **kwargs) as response:
  File "/root/tg_bot/Sharing/venv/lib/python3.11/site-packages/aiohttp/client.py", line 1167, in __aenter__
    self._resp = await self._coro
                 ^^^^^^^^^^^^^^^^
  File "/root/tg_bot/Sharing/venv/lib/python3.11/site-packages/aiohttp/client.py", line 586, in _request
    await resp.start(conn)
  File "/root/tg_bot/Sharing/venv/lib/python3.11/site-packages/aiohttp/client_reqrep.py", line 905, in start
    message, payload = await protocol.read()  # type: ignore[union-attr]
                       ^^^^^^^^^^^^^^^^^^^^^
  File "/root/tg_bot/Sharing/venv/lib/python3.11/site-packages/aiohttp/streams.py", line 616, in read
    await self._waiter
aiohttp.client_exceptions.ClientOSError: [Errno 104] Connection reset by peer

During handling of the above exception, another exception occurred:

Traceback (most recent call last):
  File "/root/tg_bot/Sharing/venv/lib/python3.11/site-packages/aiogram/dispatcher/dispatcher.py", line 381, in start_polling
    updates = await self.bot.get_updates(
              ^^^^^^^^^^^^^^^^^^^^^^^^^^^
  File "/root/tg_bot/Sharing/venv/lib/python3.11/site-packages/aiogram/bot/bot.py", line 110, in get_updates
    result = await self.request(api.Methods.GET_UPDATES, payload)
             ^^^^^^^^^^^^^^^^^^^^^^^^^^^^^^^^^^^^^^^^^^^^^^^^^^^^
  File "/root/tg_bot/Sharing/venv/lib/python3.11/site-packages/aiogram/bot/base.py", line 236, in request
    return await api.make_request(await self.get_session(), self.server, self.__token, method, data, files,
           ^^^^^^^^^^^^^^^^^^^^^^^^^^^^^^^^^^^^^^^^^^^^^^^^^^^^^^^^^^^^^^^^^^^^^^^^^^^^^^^^^^^^^^^^^^^^^^^^
  File "/root/tg_bot/Sharing/venv/lib/python3.11/site-packages/aiogram/bot/api.py", line 142, in make_request
    raise exceptions.NetworkError(f"aiohttp client throws an error: {e.__class__.__name__}: {e}")
aiogram.utils.exceptions.NetworkError: Aiohttp client throws an error: ClientOSError: [Errno 104] Connection reset by peer
2025-09-19 02:00:32,511 - ERROR - Cause exception while getting updates.
Traceback (most recent call last):
  File "/root/tg_bot/Sharing/venv/lib/python3.11/site-packages/aiogram/bot/api.py", line 139, in make_request
    async with session.post(url, data=req, **kwargs) as response:
  File "/root/tg_bot/Sharing/venv/lib/python3.11/site-packages/aiohttp/client.py", line 1167, in __aenter__
    self._resp = await self._coro
                 ^^^^^^^^^^^^^^^^
  File "/root/tg_bot/Sharing/venv/lib/python3.11/site-packages/aiohttp/client.py", line 586, in _request
    await resp.start(conn)
  File "/root/tg_bot/Sharing/venv/lib/python3.11/site-packages/aiohttp/client_reqrep.py", line 905, in start
    message, payload = await protocol.read()  # type: ignore[union-attr]
                       ^^^^^^^^^^^^^^^^^^^^^
  File "/root/tg_bot/Sharing/venv/lib/python3.11/site-packages/aiohttp/streams.py", line 616, in read
    await self._waiter
aiohttp.client_exceptions.ClientOSError: [Errno 104] Connection reset by peer

During handling of the above exception, another exception occurred:

Traceback (most recent call last):
  File "/root/tg_bot/Sharing/venv/lib/python3.11/site-packages/aiogram/dispatcher/dispatcher.py", line 381, in start_polling
    updates = await self.bot.get_updates(
              ^^^^^^^^^^^^^^^^^^^^^^^^^^^
  File "/root/tg_bot/Sharing/venv/lib/python3.11/site-packages/aiogram/bot/bot.py", line 110, in get_updates
    result = await self.request(api.Methods.GET_UPDATES, payload)
             ^^^^^^^^^^^^^^^^^^^^^^^^^^^^^^^^^^^^^^^^^^^^^^^^^^^^
  File "/root/tg_bot/Sharing/venv/lib/python3.11/site-packages/aiogram/bot/base.py", line 236, in request
    return await api.make_request(await self.get_session(), self.server, self.__token, method, data, files,
           ^^^^^^^^^^^^^^^^^^^^^^^^^^^^^^^^^^^^^^^^^^^^^^^^^^^^^^^^^^^^^^^^^^^^^^^^^^^^^^^^^^^^^^^^^^^^^^^^
  File "/root/tg_bot/Sharing/venv/lib/python3.11/site-packages/aiogram/bot/api.py", line 142, in make_request
    raise exceptions.NetworkError(f"aiohttp client throws an error: {e.__class__.__name__}: {e}")
aiogram.utils.exceptions.NetworkError: Aiohttp client throws an error: ClientOSError: [Errno 104] Connection reset by peer
2025-09-19 15:24:26,467 - ERROR - Task exception was never retrieved
future: <Task finished name='Task-16460' coro=<Dispatcher._process_polling_updates() done, defined at /root/tg_bot/Sharing/venv/lib/python3.11/site-packages/aiogram/dispatcher/dispatcher.py:407> exception=CantParseEntities('Can\'t parse entities: unsupported start tag "номер" at byte offset 43')>
Traceback (most recent call last):
  File "/root/tg_bot/Sharing/venv/lib/python3.11/site-packages/aiogram/dispatcher/dispatcher.py", line 415, in _process_polling_updates
    for responses in itertools.chain.from_iterable(await self.process_updates(updates, fast)):
                                                   ^^^^^^^^^^^^^^^^^^^^^^^^^^^^^^^^^^^^^^^^^
  File "/root/tg_bot/Sharing/venv/lib/python3.11/site-packages/aiogram/dispatcher/dispatcher.py", line 235, in process_updates
    return await asyncio.gather(*tasks)
           ^^^^^^^^^^^^^^^^^^^^^^^^^^^^
  File "/root/tg_bot/Sharing/venv/lib/python3.11/site-packages/aiogram/dispatcher/handler.py", line 117, in notify
    response = await handler_obj.handler(*args, **partial_data)
               ^^^^^^^^^^^^^^^^^^^^^^^^^^^^^^^^^^^^^^^^^^^^^^^^
  File "/root/tg_bot/Sharing/venv/lib/python3.11/site-packages/aiogram/dispatcher/dispatcher.py", line 256, in process_update
    return await self.message_handlers.notify(update.message)
           ^^^^^^^^^^^^^^^^^^^^^^^^^^^^^^^^^^^^^^^^^^^^^^^^^^
  File "/root/tg_bot/Sharing/venv/lib/python3.11/site-packages/aiogram/dispatcher/handler.py", line 117, in notify
    response = await handler_obj.handler(*args, **partial_data)
               ^^^^^^^^^^^^^^^^^^^^^^^^^^^^^^^^^^^^^^^^^^^^^^^^
  File "/root/tg_bot/Sharing/handlers.py", line 316, in find_scooter_handler
    await message.reply(
  File "/root/tg_bot/Sharing/venv/lib/python3.11/site-packages/aiogram/types/message.py", line 1687, in reply
    return await self.bot.send_message(
           ^^^^^^^^^^^^^^^^^^^^^^^^^^^^
  File "/root/tg_bot/Sharing/venv/lib/python3.11/site-packages/aiogram/bot/bot.py", line 346, in send_message
    result = await self.request(api.Methods.SEND_MESSAGE, payload)
             ^^^^^^^^^^^^^^^^^^^^^^^^^^^^^^^^^^^^^^^^^^^^^^^^^^^^^
  File "/root/tg_bot/Sharing/venv/lib/python3.11/site-packages/aiogram/bot/base.py", line 236, in request
    return await api.make_request(await self.get_session(), self.server, self.__token, method, data, files,
           ^^^^^^^^^^^^^^^^^^^^^^^^^^^^^^^^^^^^^^^^^^^^^^^^^^^^^^^^^^^^^^^^^^^^^^^^^^^^^^^^^^^^^^^^^^^^^^^^
  File "/root/tg_bot/Sharing/venv/lib/python3.11/site-packages/aiogram/bot/api.py", line 140, in make_request
    return check_result(method, response.content_type, response.status, await response.text())
           ^^^^^^^^^^^^^^^^^^^^^^^^^^^^^^^^^^^^^^^^^^^^^^^^^^^^^^^^^^^^^^^^^^^^^^^^^^^^^^^^^^^
  File "/root/tg_bot/Sharing/venv/lib/python3.11/site-packages/aiogram/bot/api.py", line 115, in check_result
    exceptions.BadRequest.detect(description)
  File "/root/tg_bot/Sharing/venv/lib/python3.11/site-packages/aiogram/utils/exceptions.py", line 140, in detect
    raise err(cls.text or description)
aiogram.utils.exceptions.CantParseEntities: Can't parse entities: unsupported start tag "номер" at byte offset 43
2025-09-21 02:57:21,921 - INFO - Bot: eom_master_inspector [@eom_master_inspectorbot]
2025-09-21 02:57:22,076 - WARNING - Updates were skipped successfully.
2025-09-21 02:57:22,358 - INFO - Start polling.
2025-09-21 13:57:02,269 - ERROR - Task exception was never retrieved
future: <Task finished name='Task-5361' coro=<Dispatcher._process_polling_updates() done, defined at /root/tg_bot/Sharing/venv/lib/python3.11/site-packages/aiogram/dispatcher/dispatcher.py:407> exception=BadRequest('Message to be replied not found')>
Traceback (most recent call last):
  File "/root/tg_bot/Sharing/venv/lib/python3.11/site-packages/aiogram/dispatcher/dispatcher.py", line 415, in _process_polling_updates
    for responses in itertools.chain.from_iterable(await self.process_updates(updates, fast)):
                                                   ^^^^^^^^^^^^^^^^^^^^^^^^^^^^^^^^^^^^^^^^^
  File "/root/tg_bot/Sharing/venv/lib/python3.11/site-packages/aiogram/dispatcher/dispatcher.py", line 235, in process_updates
    return await asyncio.gather(*tasks)
           ^^^^^^^^^^^^^^^^^^^^^^^^^^^^
  File "/root/tg_bot/Sharing/venv/lib/python3.11/site-packages/aiogram/dispatcher/handler.py", line 117, in notify
    response = await handler_obj.handler(*args, **partial_data)
               ^^^^^^^^^^^^^^^^^^^^^^^^^^^^^^^^^^^^^^^^^^^^^^^^
  File "/root/tg_bot/Sharing/venv/lib/python3.11/site-packages/aiogram/dispatcher/dispatcher.py", line 256, in process_update
    return await self.message_handlers.notify(update.message)
           ^^^^^^^^^^^^^^^^^^^^^^^^^^^^^^^^^^^^^^^^^^^^^^^^^^
  File "/root/tg_bot/Sharing/venv/lib/python3.11/site-packages/aiogram/dispatcher/handler.py", line 117, in notify
    response = await handler_obj.handler(*args, **partial_data)
               ^^^^^^^^^^^^^^^^^^^^^^^^^^^^^^^^^^^^^^^^^^^^^^^^
  File "/root/tg_bot/Sharing/handlers.py", line 102, in handle_photo_messages
    await process_scooter_text(message, message.caption)
  File "/root/tg_bot/Sharing/handlers.py", line 92, in process_scooter_text
    await message.reply("\n".join(response_parts), parse_mode="HTML")
  File "/root/tg_bot/Sharing/venv/lib/python3.11/site-packages/aiogram/types/message.py", line 1687, in reply
    return await self.bot.send_message(
           ^^^^^^^^^^^^^^^^^^^^^^^^^^^^
  File "/root/tg_bot/Sharing/venv/lib/python3.11/site-packages/aiogram/bot/bot.py", line 346, in send_message
    result = await self.request(api.Methods.SEND_MESSAGE, payload)
             ^^^^^^^^^^^^^^^^^^^^^^^^^^^^^^^^^^^^^^^^^^^^^^^^^^^^^
  File "/root/tg_bot/Sharing/venv/lib/python3.11/site-packages/aiogram/bot/base.py", line 236, in request
    return await api.make_request(await self.get_session(), self.server, self.__token, method, data, files,
           ^^^^^^^^^^^^^^^^^^^^^^^^^^^^^^^^^^^^^^^^^^^^^^^^^^^^^^^^^^^^^^^^^^^^^^^^^^^^^^^^^^^^^^^^^^^^^^^^
  File "/root/tg_bot/Sharing/venv/lib/python3.11/site-packages/aiogram/bot/api.py", line 140, in make_request
    return check_result(method, response.content_type, response.status, await response.text())
           ^^^^^^^^^^^^^^^^^^^^^^^^^^^^^^^^^^^^^^^^^^^^^^^^^^^^^^^^^^^^^^^^^^^^^^^^^^^^^^^^^^^
  File "/root/tg_bot/Sharing/venv/lib/python3.11/site-packages/aiogram/bot/api.py", line 115, in check_result
    exceptions.BadRequest.detect(description)
  File "/root/tg_bot/Sharing/venv/lib/python3.11/site-packages/aiogram/utils/exceptions.py", line 141, in detect
    raise cls(description)
aiogram.utils.exceptions.BadRequest: Message to be replied not found
2025-09-22 09:15:29,030 - ERROR - Cause exception while getting updates.
Traceback (most recent call last):
  File "/root/tg_bot/Sharing/venv/lib/python3.11/site-packages/aiogram/dispatcher/dispatcher.py", line 381, in start_polling
    updates = await self.bot.get_updates(
              ^^^^^^^^^^^^^^^^^^^^^^^^^^^
  File "/root/tg_bot/Sharing/venv/lib/python3.11/site-packages/aiogram/bot/bot.py", line 110, in get_updates
    result = await self.request(api.Methods.GET_UPDATES, payload)
             ^^^^^^^^^^^^^^^^^^^^^^^^^^^^^^^^^^^^^^^^^^^^^^^^^^^^
  File "/root/tg_bot/Sharing/venv/lib/python3.11/site-packages/aiogram/bot/base.py", line 236, in request
    return await api.make_request(await self.get_session(), self.server, self.__token, method, data, files,
           ^^^^^^^^^^^^^^^^^^^^^^^^^^^^^^^^^^^^^^^^^^^^^^^^^^^^^^^^^^^^^^^^^^^^^^^^^^^^^^^^^^^^^^^^^^^^^^^^
  File "/root/tg_bot/Sharing/venv/lib/python3.11/site-packages/aiogram/bot/api.py", line 139, in make_request
    async with session.post(url, data=req, **kwargs) as response:
  File "/root/tg_bot/Sharing/venv/lib/python3.11/site-packages/aiohttp/client.py", line 1167, in __aenter__
    self._resp = await self._coro
                 ^^^^^^^^^^^^^^^^
  File "/root/tg_bot/Sharing/venv/lib/python3.11/site-packages/aiohttp/client.py", line 586, in _request
    await resp.start(conn)
  File "/root/tg_bot/Sharing/venv/lib/python3.11/site-packages/aiohttp/client_reqrep.py", line 900, in start
    with self._timer:
  File "/root/tg_bot/Sharing/venv/lib/python3.11/site-packages/aiohttp/helpers.py", line 725, in __exit__
    raise asyncio.TimeoutError from None
TimeoutError
2025-09-22 09:15:34,926 - ERROR - Task exception was never retrieved
future: <Task finished name='Task-14882' coro=<Dispatcher._process_polling_updates() done, defined at /root/tg_bot/Sharing/venv/lib/python3.11/site-packages/aiogram/dispatcher/dispatcher.py:407> exception=BadRequest('Message to be replied not found')>
Traceback (most recent call last):
  File "/root/tg_bot/Sharing/venv/lib/python3.11/site-packages/aiogram/dispatcher/dispatcher.py", line 415, in _process_polling_updates
    for responses in itertools.chain.from_iterable(await self.process_updates(updates, fast)):
                                                   ^^^^^^^^^^^^^^^^^^^^^^^^^^^^^^^^^^^^^^^^^
  File "/root/tg_bot/Sharing/venv/lib/python3.11/site-packages/aiogram/dispatcher/dispatcher.py", line 235, in process_updates
    return await asyncio.gather(*tasks)
           ^^^^^^^^^^^^^^^^^^^^^^^^^^^^
  File "/root/tg_bot/Sharing/venv/lib/python3.11/site-packages/aiogram/dispatcher/handler.py", line 117, in notify
    response = await handler_obj.handler(*args, **partial_data)
               ^^^^^^^^^^^^^^^^^^^^^^^^^^^^^^^^^^^^^^^^^^^^^^^^
  File "/root/tg_bot/Sharing/venv/lib/python3.11/site-packages/aiogram/dispatcher/dispatcher.py", line 256, in process_update
    return await self.message_handlers.notify(update.message)
           ^^^^^^^^^^^^^^^^^^^^^^^^^^^^^^^^^^^^^^^^^^^^^^^^^^
  File "/root/tg_bot/Sharing/venv/lib/python3.11/site-packages/aiogram/dispatcher/handler.py", line 117, in notify
    response = await handler_obj.handler(*args, **partial_data)
               ^^^^^^^^^^^^^^^^^^^^^^^^^^^^^^^^^^^^^^^^^^^^^^^^
  File "/root/tg_bot/Sharing/handlers.py", line 102, in handle_photo_messages
    await process_scooter_text(message, message.caption)
  File "/root/tg_bot/Sharing/handlers.py", line 92, in process_scooter_text
    await message.reply("\n".join(response_parts), parse_mode="HTML")
  File "/root/tg_bot/Sharing/venv/lib/python3.11/site-packages/aiogram/types/message.py", line 1687, in reply
    return await self.bot.send_message(
           ^^^^^^^^^^^^^^^^^^^^^^^^^^^^
  File "/root/tg_bot/Sharing/venv/lib/python3.11/site-packages/aiogram/bot/bot.py", line 346, in send_message
    result = await self.request(api.Methods.SEND_MESSAGE, payload)
             ^^^^^^^^^^^^^^^^^^^^^^^^^^^^^^^^^^^^^^^^^^^^^^^^^^^^^
  File "/root/tg_bot/Sharing/venv/lib/python3.11/site-packages/aiogram/bot/base.py", line 236, in request
    return await api.make_request(await self.get_session(), self.server, self.__token, method, data, files,
           ^^^^^^^^^^^^^^^^^^^^^^^^^^^^^^^^^^^^^^^^^^^^^^^^^^^^^^^^^^^^^^^^^^^^^^^^^^^^^^^^^^^^^^^^^^^^^^^^
  File "/root/tg_bot/Sharing/venv/lib/python3.11/site-packages/aiogram/bot/api.py", line 140, in make_request
    return check_result(method, response.content_type, response.status, await response.text())
           ^^^^^^^^^^^^^^^^^^^^^^^^^^^^^^^^^^^^^^^^^^^^^^^^^^^^^^^^^^^^^^^^^^^^^^^^^^^^^^^^^^^
  File "/root/tg_bot/Sharing/venv/lib/python3.11/site-packages/aiogram/bot/api.py", line 115, in check_result
    exceptions.BadRequest.detect(description)
  File "/root/tg_bot/Sharing/venv/lib/python3.11/site-packages/aiogram/utils/exceptions.py", line 141, in detect
    raise cls(description)
aiogram.utils.exceptions.BadRequest: Message to be replied not found
2025-09-22 09:15:37,947 - ERROR - Task exception was never retrieved
future: <Task finished name='Task-15322' coro=<Dispatcher._process_polling_updates() done, defined at /root/tg_bot/Sharing/venv/lib/python3.11/site-packages/aiogram/dispatcher/dispatcher.py:407> exception=BadRequest('Message to be replied not found')>
Traceback (most recent call last):
  File "/root/tg_bot/Sharing/venv/lib/python3.11/site-packages/aiogram/dispatcher/dispatcher.py", line 415, in _process_polling_updates
    for responses in itertools.chain.from_iterable(await self.process_updates(updates, fast)):
                                                   ^^^^^^^^^^^^^^^^^^^^^^^^^^^^^^^^^^^^^^^^^
  File "/root/tg_bot/Sharing/venv/lib/python3.11/site-packages/aiogram/dispatcher/dispatcher.py", line 235, in process_updates
    return await asyncio.gather(*tasks)
           ^^^^^^^^^^^^^^^^^^^^^^^^^^^^
  File "/root/tg_bot/Sharing/venv/lib/python3.11/site-packages/aiogram/dispatcher/handler.py", line 117, in notify
    response = await handler_obj.handler(*args, **partial_data)
               ^^^^^^^^^^^^^^^^^^^^^^^^^^^^^^^^^^^^^^^^^^^^^^^^
  File "/root/tg_bot/Sharing/venv/lib/python3.11/site-packages/aiogram/dispatcher/dispatcher.py", line 256, in process_update
    return await self.message_handlers.notify(update.message)
           ^^^^^^^^^^^^^^^^^^^^^^^^^^^^^^^^^^^^^^^^^^^^^^^^^^
  File "/root/tg_bot/Sharing/venv/lib/python3.11/site-packages/aiogram/dispatcher/handler.py", line 117, in notify
    response = await handler_obj.handler(*args, **partial_data)
               ^^^^^^^^^^^^^^^^^^^^^^^^^^^^^^^^^^^^^^^^^^^^^^^^
  File "/root/tg_bot/Sharing/handlers.py", line 102, in handle_photo_messages
    await process_scooter_text(message, message.caption)
  File "/root/tg_bot/Sharing/handlers.py", line 92, in process_scooter_text
    await message.reply("\n".join(response_parts), parse_mode="HTML")
  File "/root/tg_bot/Sharing/venv/lib/python3.11/site-packages/aiogram/types/message.py", line 1687, in reply
    return await self.bot.send_message(
           ^^^^^^^^^^^^^^^^^^^^^^^^^^^^
  File "/root/tg_bot/Sharing/venv/lib/python3.11/site-packages/aiogram/bot/bot.py", line 346, in send_message
    result = await self.request(api.Methods.SEND_MESSAGE, payload)
             ^^^^^^^^^^^^^^^^^^^^^^^^^^^^^^^^^^^^^^^^^^^^^^^^^^^^^
  File "/root/tg_bot/Sharing/venv/lib/python3.11/site-packages/aiogram/bot/base.py", line 236, in request
    return await api.make_request(await self.get_session(), self.server, self.__token, method, data, files,
           ^^^^^^^^^^^^^^^^^^^^^^^^^^^^^^^^^^^^^^^^^^^^^^^^^^^^^^^^^^^^^^^^^^^^^^^^^^^^^^^^^^^^^^^^^^^^^^^^
  File "/root/tg_bot/Sharing/venv/lib/python3.11/site-packages/aiogram/bot/api.py", line 140, in make_request
    return check_result(method, response.content_type, response.status, await response.text())
           ^^^^^^^^^^^^^^^^^^^^^^^^^^^^^^^^^^^^^^^^^^^^^^^^^^^^^^^^^^^^^^^^^^^^^^^^^^^^^^^^^^^
  File "/root/tg_bot/Sharing/venv/lib/python3.11/site-packages/aiogram/bot/api.py", line 115, in check_result
    exceptions.BadRequest.detect(description)
  File "/root/tg_bot/Sharing/venv/lib/python3.11/site-packages/aiogram/utils/exceptions.py", line 141, in detect
    raise cls(description)
aiogram.utils.exceptions.BadRequest: Message to be replied not found
2025-09-22 09:15:38,453 - ERROR - Task exception was never retrieved
future: <Task finished name='Task-15487' coro=<Dispatcher._process_polling_updates() done, defined at /root/tg_bot/Sharing/venv/lib/python3.11/site-packages/aiogram/dispatcher/dispatcher.py:407> exception=BadRequest('Message to be replied not found')>
Traceback (most recent call last):
  File "/root/tg_bot/Sharing/venv/lib/python3.11/site-packages/aiogram/dispatcher/dispatcher.py", line 415, in _process_polling_updates
    for responses in itertools.chain.from_iterable(await self.process_updates(updates, fast)):
                                                   ^^^^^^^^^^^^^^^^^^^^^^^^^^^^^^^^^^^^^^^^^
  File "/root/tg_bot/Sharing/venv/lib/python3.11/site-packages/aiogram/dispatcher/dispatcher.py", line 235, in process_updates
    return await asyncio.gather(*tasks)
           ^^^^^^^^^^^^^^^^^^^^^^^^^^^^
  File "/root/tg_bot/Sharing/venv/lib/python3.11/site-packages/aiogram/dispatcher/handler.py", line 117, in notify
    response = await handler_obj.handler(*args, **partial_data)
               ^^^^^^^^^^^^^^^^^^^^^^^^^^^^^^^^^^^^^^^^^^^^^^^^
  File "/root/tg_bot/Sharing/venv/lib/python3.11/site-packages/aiogram/dispatcher/dispatcher.py", line 256, in process_update
    return await self.message_handlers.notify(update.message)
           ^^^^^^^^^^^^^^^^^^^^^^^^^^^^^^^^^^^^^^^^^^^^^^^^^^
  File "/root/tg_bot/Sharing/venv/lib/python3.11/site-packages/aiogram/dispatcher/handler.py", line 117, in notify
    response = await handler_obj.handler(*args, **partial_data)
               ^^^^^^^^^^^^^^^^^^^^^^^^^^^^^^^^^^^^^^^^^^^^^^^^
  File "/root/tg_bot/Sharing/handlers.py", line 102, in handle_photo_messages
    await process_scooter_text(message, message.caption)
  File "/root/tg_bot/Sharing/handlers.py", line 92, in process_scooter_text
    await message.reply("\n".join(response_parts), parse_mode="HTML")
  File "/root/tg_bot/Sharing/venv/lib/python3.11/site-packages/aiogram/types/message.py", line 1687, in reply
    return await self.bot.send_message(
           ^^^^^^^^^^^^^^^^^^^^^^^^^^^^
  File "/root/tg_bot/Sharing/venv/lib/python3.11/site-packages/aiogram/bot/bot.py", line 346, in send_message
    result = await self.request(api.Methods.SEND_MESSAGE, payload)
             ^^^^^^^^^^^^^^^^^^^^^^^^^^^^^^^^^^^^^^^^^^^^^^^^^^^^^
  File "/root/tg_bot/Sharing/venv/lib/python3.11/site-packages/aiogram/bot/base.py", line 236, in request
    return await api.make_request(await self.get_session(), self.server, self.__token, method, data, files,
           ^^^^^^^^^^^^^^^^^^^^^^^^^^^^^^^^^^^^^^^^^^^^^^^^^^^^^^^^^^^^^^^^^^^^^^^^^^^^^^^^^^^^^^^^^^^^^^^^
  File "/root/tg_bot/Sharing/venv/lib/python3.11/site-packages/aiogram/bot/api.py", line 140, in make_request
    return check_result(method, response.content_type, response.status, await response.text())
           ^^^^^^^^^^^^^^^^^^^^^^^^^^^^^^^^^^^^^^^^^^^^^^^^^^^^^^^^^^^^^^^^^^^^^^^^^^^^^^^^^^^
  File "/root/tg_bot/Sharing/venv/lib/python3.11/site-packages/aiogram/bot/api.py", line 115, in check_result
    exceptions.BadRequest.detect(description)
  File "/root/tg_bot/Sharing/venv/lib/python3.11/site-packages/aiogram/utils/exceptions.py", line 141, in detect
    raise cls(description)
aiogram.utils.exceptions.BadRequest: Message to be replied not found
2025-09-22 09:15:38,542 - ERROR - Task exception was never retrieved
future: <Task finished name='Task-15664' coro=<Dispatcher._process_polling_updates() done, defined at /root/tg_bot/Sharing/venv/lib/python3.11/site-packages/aiogram/dispatcher/dispatcher.py:407> exception=BadRequest('Message to be replied not found')>
Traceback (most recent call last):
  File "/root/tg_bot/Sharing/venv/lib/python3.11/site-packages/aiogram/dispatcher/dispatcher.py", line 415, in _process_polling_updates
    for responses in itertools.chain.from_iterable(await self.process_updates(updates, fast)):
                                                   ^^^^^^^^^^^^^^^^^^^^^^^^^^^^^^^^^^^^^^^^^
  File "/root/tg_bot/Sharing/venv/lib/python3.11/site-packages/aiogram/dispatcher/dispatcher.py", line 235, in process_updates
    return await asyncio.gather(*tasks)
           ^^^^^^^^^^^^^^^^^^^^^^^^^^^^
  File "/root/tg_bot/Sharing/venv/lib/python3.11/site-packages/aiogram/dispatcher/handler.py", line 117, in notify
    response = await handler_obj.handler(*args, **partial_data)
               ^^^^^^^^^^^^^^^^^^^^^^^^^^^^^^^^^^^^^^^^^^^^^^^^
  File "/root/tg_bot/Sharing/venv/lib/python3.11/site-packages/aiogram/dispatcher/dispatcher.py", line 256, in process_update
    return await self.message_handlers.notify(update.message)
           ^^^^^^^^^^^^^^^^^^^^^^^^^^^^^^^^^^^^^^^^^^^^^^^^^^
  File "/root/tg_bot/Sharing/venv/lib/python3.11/site-packages/aiogram/dispatcher/handler.py", line 117, in notify
    response = await handler_obj.handler(*args, **partial_data)
               ^^^^^^^^^^^^^^^^^^^^^^^^^^^^^^^^^^^^^^^^^^^^^^^^
  File "/root/tg_bot/Sharing/handlers.py", line 102, in handle_photo_messages
    await process_scooter_text(message, message.caption)
  File "/root/tg_bot/Sharing/handlers.py", line 92, in process_scooter_text
    await message.reply("\n".join(response_parts), parse_mode="HTML")
  File "/root/tg_bot/Sharing/venv/lib/python3.11/site-packages/aiogram/types/message.py", line 1687, in reply
    return await self.bot.send_message(
           ^^^^^^^^^^^^^^^^^^^^^^^^^^^^
  File "/root/tg_bot/Sharing/venv/lib/python3.11/site-packages/aiogram/bot/bot.py", line 346, in send_message
    result = await self.request(api.Methods.SEND_MESSAGE, payload)
             ^^^^^^^^^^^^^^^^^^^^^^^^^^^^^^^^^^^^^^^^^^^^^^^^^^^^^
  File "/root/tg_bot/Sharing/venv/lib/python3.11/site-packages/aiogram/bot/base.py", line 236, in request
    return await api.make_request(await self.get_session(), self.server, self.__token, method, data, files,
           ^^^^^^^^^^^^^^^^^^^^^^^^^^^^^^^^^^^^^^^^^^^^^^^^^^^^^^^^^^^^^^^^^^^^^^^^^^^^^^^^^^^^^^^^^^^^^^^^
  File "/root/tg_bot/Sharing/venv/lib/python3.11/site-packages/aiogram/bot/api.py", line 140, in make_request
    return check_result(method, response.content_type, response.status, await response.text())
           ^^^^^^^^^^^^^^^^^^^^^^^^^^^^^^^^^^^^^^^^^^^^^^^^^^^^^^^^^^^^^^^^^^^^^^^^^^^^^^^^^^^
  File "/root/tg_bot/Sharing/venv/lib/python3.11/site-packages/aiogram/bot/api.py", line 115, in check_result
    exceptions.BadRequest.detect(description)
  File "/root/tg_bot/Sharing/venv/lib/python3.11/site-packages/aiogram/utils/exceptions.py", line 141, in detect
    raise cls(description)
aiogram.utils.exceptions.BadRequest: Message to be replied not found
2025-09-22 09:15:38,918 - ERROR - Task exception was never retrieved
future: <Task finished name='Task-15160' coro=<Dispatcher._process_polling_updates() done, defined at /root/tg_bot/Sharing/venv/lib/python3.11/site-packages/aiogram/dispatcher/dispatcher.py:407> exception=BadRequest('Message to be replied not found')>
Traceback (most recent call last):
  File "/root/tg_bot/Sharing/venv/lib/python3.11/site-packages/aiogram/dispatcher/dispatcher.py", line 415, in _process_polling_updates
    for responses in itertools.chain.from_iterable(await self.process_updates(updates, fast)):
                                                   ^^^^^^^^^^^^^^^^^^^^^^^^^^^^^^^^^^^^^^^^^
  File "/root/tg_bot/Sharing/venv/lib/python3.11/site-packages/aiogram/dispatcher/dispatcher.py", line 235, in process_updates
    return await asyncio.gather(*tasks)
           ^^^^^^^^^^^^^^^^^^^^^^^^^^^^
  File "/root/tg_bot/Sharing/venv/lib/python3.11/site-packages/aiogram/dispatcher/handler.py", line 117, in notify
    response = await handler_obj.handler(*args, **partial_data)
               ^^^^^^^^^^^^^^^^^^^^^^^^^^^^^^^^^^^^^^^^^^^^^^^^
  File "/root/tg_bot/Sharing/venv/lib/python3.11/site-packages/aiogram/dispatcher/dispatcher.py", line 256, in process_update
    return await self.message_handlers.notify(update.message)
           ^^^^^^^^^^^^^^^^^^^^^^^^^^^^^^^^^^^^^^^^^^^^^^^^^^
  File "/root/tg_bot/Sharing/venv/lib/python3.11/site-packages/aiogram/dispatcher/handler.py", line 117, in notify
    response = await handler_obj.handler(*args, **partial_data)
               ^^^^^^^^^^^^^^^^^^^^^^^^^^^^^^^^^^^^^^^^^^^^^^^^
  File "/root/tg_bot/Sharing/handlers.py", line 102, in handle_photo_messages
    await process_scooter_text(message, message.caption)
  File "/root/tg_bot/Sharing/handlers.py", line 92, in process_scooter_text
    await message.reply("\n".join(response_parts), parse_mode="HTML")
  File "/root/tg_bot/Sharing/venv/lib/python3.11/site-packages/aiogram/types/message.py", line 1687, in reply
    return await self.bot.send_message(
           ^^^^^^^^^^^^^^^^^^^^^^^^^^^^
  File "/root/tg_bot/Sharing/venv/lib/python3.11/site-packages/aiogram/bot/bot.py", line 346, in send_message
    result = await self.request(api.Methods.SEND_MESSAGE, payload)
             ^^^^^^^^^^^^^^^^^^^^^^^^^^^^^^^^^^^^^^^^^^^^^^^^^^^^^
  File "/root/tg_bot/Sharing/venv/lib/python3.11/site-packages/aiogram/bot/base.py", line 236, in request
    return await api.make_request(await self.get_session(), self.server, self.__token, method, data, files,
           ^^^^^^^^^^^^^^^^^^^^^^^^^^^^^^^^^^^^^^^^^^^^^^^^^^^^^^^^^^^^^^^^^^^^^^^^^^^^^^^^^^^^^^^^^^^^^^^^
  File "/root/tg_bot/Sharing/venv/lib/python3.11/site-packages/aiogram/bot/api.py", line 140, in make_request
    return check_result(method, response.content_type, response.status, await response.text())
           ^^^^^^^^^^^^^^^^^^^^^^^^^^^^^^^^^^^^^^^^^^^^^^^^^^^^^^^^^^^^^^^^^^^^^^^^^^^^^^^^^^^
  File "/root/tg_bot/Sharing/venv/lib/python3.11/site-packages/aiogram/bot/api.py", line 115, in check_result
    exceptions.BadRequest.detect(description)
  File "/root/tg_bot/Sharing/venv/lib/python3.11/site-packages/aiogram/utils/exceptions.py", line 141, in detect
    raise cls(description)
aiogram.utils.exceptions.BadRequest: Message to be replied not found
2025-09-22 09:15:40,253 - ERROR - Task exception was never retrieved
future: <Task finished name='Task-16185' coro=<Dispatcher._process_polling_updates() done, defined at /root/tg_bot/Sharing/venv/lib/python3.11/site-packages/aiogram/dispatcher/dispatcher.py:407> exception=BadRequest('Message to be replied not found')>
Traceback (most recent call last):
  File "/root/tg_bot/Sharing/venv/lib/python3.11/site-packages/aiogram/dispatcher/dispatcher.py", line 415, in _process_polling_updates
    for responses in itertools.chain.from_iterable(await self.process_updates(updates, fast)):
                                                   ^^^^^^^^^^^^^^^^^^^^^^^^^^^^^^^^^^^^^^^^^
  File "/root/tg_bot/Sharing/venv/lib/python3.11/site-packages/aiogram/dispatcher/dispatcher.py", line 235, in process_updates
    return await asyncio.gather(*tasks)
           ^^^^^^^^^^^^^^^^^^^^^^^^^^^^
  File "/root/tg_bot/Sharing/venv/lib/python3.11/site-packages/aiogram/dispatcher/handler.py", line 117, in notify
    response = await handler_obj.handler(*args, **partial_data)
               ^^^^^^^^^^^^^^^^^^^^^^^^^^^^^^^^^^^^^^^^^^^^^^^^
  File "/root/tg_bot/Sharing/venv/lib/python3.11/site-packages/aiogram/dispatcher/dispatcher.py", line 256, in process_update
    return await self.message_handlers.notify(update.message)
           ^^^^^^^^^^^^^^^^^^^^^^^^^^^^^^^^^^^^^^^^^^^^^^^^^^
  File "/root/tg_bot/Sharing/venv/lib/python3.11/site-packages/aiogram/dispatcher/handler.py", line 117, in notify
    response = await handler_obj.handler(*args, **partial_data)
               ^^^^^^^^^^^^^^^^^^^^^^^^^^^^^^^^^^^^^^^^^^^^^^^^
  File "/root/tg_bot/Sharing/handlers.py", line 102, in handle_photo_messages
    await process_scooter_text(message, message.caption)
  File "/root/tg_bot/Sharing/handlers.py", line 92, in process_scooter_text
    await message.reply("\n".join(response_parts), parse_mode="HTML")
  File "/root/tg_bot/Sharing/venv/lib/python3.11/site-packages/aiogram/types/message.py", line 1687, in reply
    return await self.bot.send_message(
           ^^^^^^^^^^^^^^^^^^^^^^^^^^^^
  File "/root/tg_bot/Sharing/venv/lib/python3.11/site-packages/aiogram/bot/bot.py", line 346, in send_message
    result = await self.request(api.Methods.SEND_MESSAGE, payload)
             ^^^^^^^^^^^^^^^^^^^^^^^^^^^^^^^^^^^^^^^^^^^^^^^^^^^^^
  File "/root/tg_bot/Sharing/venv/lib/python3.11/site-packages/aiogram/bot/base.py", line 236, in request
    return await api.make_request(await self.get_session(), self.server, self.__token, method, data, files,
           ^^^^^^^^^^^^^^^^^^^^^^^^^^^^^^^^^^^^^^^^^^^^^^^^^^^^^^^^^^^^^^^^^^^^^^^^^^^^^^^^^^^^^^^^^^^^^^^^
  File "/root/tg_bot/Sharing/venv/lib/python3.11/site-packages/aiogram/bot/api.py", line 140, in make_request
    return check_result(method, response.content_type, response.status, await response.text())
           ^^^^^^^^^^^^^^^^^^^^^^^^^^^^^^^^^^^^^^^^^^^^^^^^^^^^^^^^^^^^^^^^^^^^^^^^^^^^^^^^^^^
  File "/root/tg_bot/Sharing/venv/lib/python3.11/site-packages/aiogram/bot/api.py", line 115, in check_result
    exceptions.BadRequest.detect(description)
  File "/root/tg_bot/Sharing/venv/lib/python3.11/site-packages/aiogram/utils/exceptions.py", line 141, in detect
    raise cls(description)
aiogram.utils.exceptions.BadRequest: Message to be replied not found
2025-09-22 09:15:40,595 - ERROR - Task exception was never retrieved
future: <Task finished name='Task-15017' coro=<Dispatcher._process_polling_updates() done, defined at /root/tg_bot/Sharing/venv/lib/python3.11/site-packages/aiogram/dispatcher/dispatcher.py:407> exception=RetryAfter('Flood control exceeded. Retry in 5 seconds.')>
Traceback (most recent call last):
  File "/root/tg_bot/Sharing/venv/lib/python3.11/site-packages/aiogram/dispatcher/dispatcher.py", line 415, in _process_polling_updates
    for responses in itertools.chain.from_iterable(await self.process_updates(updates, fast)):
                                                   ^^^^^^^^^^^^^^^^^^^^^^^^^^^^^^^^^^^^^^^^^
  File "/root/tg_bot/Sharing/venv/lib/python3.11/site-packages/aiogram/dispatcher/dispatcher.py", line 235, in process_updates
    return await asyncio.gather(*tasks)
           ^^^^^^^^^^^^^^^^^^^^^^^^^^^^
  File "/root/tg_bot/Sharing/venv/lib/python3.11/site-packages/aiogram/dispatcher/handler.py", line 117, in notify
    response = await handler_obj.handler(*args, **partial_data)
               ^^^^^^^^^^^^^^^^^^^^^^^^^^^^^^^^^^^^^^^^^^^^^^^^
  File "/root/tg_bot/Sharing/venv/lib/python3.11/site-packages/aiogram/dispatcher/dispatcher.py", line 256, in process_update
    return await self.message_handlers.notify(update.message)
           ^^^^^^^^^^^^^^^^^^^^^^^^^^^^^^^^^^^^^^^^^^^^^^^^^^
  File "/root/tg_bot/Sharing/venv/lib/python3.11/site-packages/aiogram/dispatcher/handler.py", line 117, in notify
    response = await handler_obj.handler(*args, **partial_data)
               ^^^^^^^^^^^^^^^^^^^^^^^^^^^^^^^^^^^^^^^^^^^^^^^^
  File "/root/tg_bot/Sharing/handlers.py", line 102, in handle_photo_messages
    await process_scooter_text(message, message.caption)
  File "/root/tg_bot/Sharing/handlers.py", line 92, in process_scooter_text
    await message.reply("\n".join(response_parts), parse_mode="HTML")
  File "/root/tg_bot/Sharing/venv/lib/python3.11/site-packages/aiogram/types/message.py", line 1687, in reply
    return await self.bot.send_message(
           ^^^^^^^^^^^^^^^^^^^^^^^^^^^^
  File "/root/tg_bot/Sharing/venv/lib/python3.11/site-packages/aiogram/bot/bot.py", line 346, in send_message
    result = await self.request(api.Methods.SEND_MESSAGE, payload)
             ^^^^^^^^^^^^^^^^^^^^^^^^^^^^^^^^^^^^^^^^^^^^^^^^^^^^^
  File "/root/tg_bot/Sharing/venv/lib/python3.11/site-packages/aiogram/bot/base.py", line 236, in request
    return await api.make_request(await self.get_session(), self.server, self.__token, method, data, files,
           ^^^^^^^^^^^^^^^^^^^^^^^^^^^^^^^^^^^^^^^^^^^^^^^^^^^^^^^^^^^^^^^^^^^^^^^^^^^^^^^^^^^^^^^^^^^^^^^^
  File "/root/tg_bot/Sharing/venv/lib/python3.11/site-packages/aiogram/bot/api.py", line 140, in make_request
    return check_result(method, response.content_type, response.status, await response.text())
           ^^^^^^^^^^^^^^^^^^^^^^^^^^^^^^^^^^^^^^^^^^^^^^^^^^^^^^^^^^^^^^^^^^^^^^^^^^^^^^^^^^^
  File "/root/tg_bot/Sharing/venv/lib/python3.11/site-packages/aiogram/bot/api.py", line 111, in check_result
    raise exceptions.RetryAfter(parameters.retry_after)
aiogram.utils.exceptions.RetryAfter: Flood control exceeded. Retry in 5 seconds.
2025-09-22 09:15:40,617 - ERROR - Task exception was never retrieved
future: <Task finished name='Task-15829' coro=<Dispatcher._process_polling_updates() done, defined at /root/tg_bot/Sharing/venv/lib/python3.11/site-packages/aiogram/dispatcher/dispatcher.py:407> exception=RetryAfter('Flood control exceeded. Retry in 5 seconds.')>
Traceback (most recent call last):
  File "/root/tg_bot/Sharing/venv/lib/python3.11/site-packages/aiogram/dispatcher/dispatcher.py", line 415, in _process_polling_updates
    for responses in itertools.chain.from_iterable(await self.process_updates(updates, fast)):
                                                   ^^^^^^^^^^^^^^^^^^^^^^^^^^^^^^^^^^^^^^^^^
  File "/root/tg_bot/Sharing/venv/lib/python3.11/site-packages/aiogram/dispatcher/dispatcher.py", line 235, in process_updates
    return await asyncio.gather(*tasks)
           ^^^^^^^^^^^^^^^^^^^^^^^^^^^^
  File "/root/tg_bot/Sharing/venv/lib/python3.11/site-packages/aiogram/dispatcher/handler.py", line 117, in notify
    response = await handler_obj.handler(*args, **partial_data)
               ^^^^^^^^^^^^^^^^^^^^^^^^^^^^^^^^^^^^^^^^^^^^^^^^
  File "/root/tg_bot/Sharing/venv/lib/python3.11/site-packages/aiogram/dispatcher/dispatcher.py", line 256, in process_update
    return await self.message_handlers.notify(update.message)
           ^^^^^^^^^^^^^^^^^^^^^^^^^^^^^^^^^^^^^^^^^^^^^^^^^^
  File "/root/tg_bot/Sharing/venv/lib/python3.11/site-packages/aiogram/dispatcher/handler.py", line 117, in notify
    response = await handler_obj.handler(*args, **partial_data)
               ^^^^^^^^^^^^^^^^^^^^^^^^^^^^^^^^^^^^^^^^^^^^^^^^
  File "/root/tg_bot/Sharing/handlers.py", line 102, in handle_photo_messages
    await process_scooter_text(message, message.caption)
  File "/root/tg_bot/Sharing/handlers.py", line 92, in process_scooter_text
    await message.reply("\n".join(response_parts), parse_mode="HTML")
  File "/root/tg_bot/Sharing/venv/lib/python3.11/site-packages/aiogram/types/message.py", line 1687, in reply
    return await self.bot.send_message(
           ^^^^^^^^^^^^^^^^^^^^^^^^^^^^
  File "/root/tg_bot/Sharing/venv/lib/python3.11/site-packages/aiogram/bot/bot.py", line 346, in send_message
    result = await self.request(api.Methods.SEND_MESSAGE, payload)
             ^^^^^^^^^^^^^^^^^^^^^^^^^^^^^^^^^^^^^^^^^^^^^^^^^^^^^
  File "/root/tg_bot/Sharing/venv/lib/python3.11/site-packages/aiogram/bot/base.py", line 236, in request
    return await api.make_request(await self.get_session(), self.server, self.__token, method, data, files,
           ^^^^^^^^^^^^^^^^^^^^^^^^^^^^^^^^^^^^^^^^^^^^^^^^^^^^^^^^^^^^^^^^^^^^^^^^^^^^^^^^^^^^^^^^^^^^^^^^
  File "/root/tg_bot/Sharing/venv/lib/python3.11/site-packages/aiogram/bot/api.py", line 140, in make_request
    return check_result(method, response.content_type, response.status, await response.text())
           ^^^^^^^^^^^^^^^^^^^^^^^^^^^^^^^^^^^^^^^^^^^^^^^^^^^^^^^^^^^^^^^^^^^^^^^^^^^^^^^^^^^
  File "/root/tg_bot/Sharing/venv/lib/python3.11/site-packages/aiogram/bot/api.py", line 111, in check_result
    raise exceptions.RetryAfter(parameters.retry_after)
aiogram.utils.exceptions.RetryAfter: Flood control exceeded. Retry in 5 seconds.
2025-09-22 09:15:40,619 - ERROR - Task exception was never retrieved
future: <Task finished name='Task-15999' coro=<Dispatcher._process_polling_updates() done, defined at /root/tg_bot/Sharing/venv/lib/python3.11/site-packages/aiogram/dispatcher/dispatcher.py:407> exception=RetryAfter('Flood control exceeded. Retry in 5 seconds.')>
Traceback (most recent call last):
  File "/root/tg_bot/Sharing/venv/lib/python3.11/site-packages/aiogram/dispatcher/dispatcher.py", line 415, in _process_polling_updates
    for responses in itertools.chain.from_iterable(await self.process_updates(updates, fast)):
                                                   ^^^^^^^^^^^^^^^^^^^^^^^^^^^^^^^^^^^^^^^^^
  File "/root/tg_bot/Sharing/venv/lib/python3.11/site-packages/aiogram/dispatcher/dispatcher.py", line 235, in process_updates
    return await asyncio.gather(*tasks)
           ^^^^^^^^^^^^^^^^^^^^^^^^^^^^
  File "/root/tg_bot/Sharing/venv/lib/python3.11/site-packages/aiogram/dispatcher/handler.py", line 117, in notify
    response = await handler_obj.handler(*args, **partial_data)
               ^^^^^^^^^^^^^^^^^^^^^^^^^^^^^^^^^^^^^^^^^^^^^^^^
  File "/root/tg_bot/Sharing/venv/lib/python3.11/site-packages/aiogram/dispatcher/dispatcher.py", line 256, in process_update
    return await self.message_handlers.notify(update.message)
           ^^^^^^^^^^^^^^^^^^^^^^^^^^^^^^^^^^^^^^^^^^^^^^^^^^
  File "/root/tg_bot/Sharing/venv/lib/python3.11/site-packages/aiogram/dispatcher/handler.py", line 117, in notify
    response = await handler_obj.handler(*args, **partial_data)
               ^^^^^^^^^^^^^^^^^^^^^^^^^^^^^^^^^^^^^^^^^^^^^^^^
  File "/root/tg_bot/Sharing/handlers.py", line 102, in handle_photo_messages
    await process_scooter_text(message, message.caption)
  File "/root/tg_bot/Sharing/handlers.py", line 92, in process_scooter_text
    await message.reply("\n".join(response_parts), parse_mode="HTML")
  File "/root/tg_bot/Sharing/venv/lib/python3.11/site-packages/aiogram/types/message.py", line 1687, in reply
    return await self.bot.send_message(
           ^^^^^^^^^^^^^^^^^^^^^^^^^^^^
  File "/root/tg_bot/Sharing/venv/lib/python3.11/site-packages/aiogram/bot/bot.py", line 346, in send_message
    result = await self.request(api.Methods.SEND_MESSAGE, payload)
             ^^^^^^^^^^^^^^^^^^^^^^^^^^^^^^^^^^^^^^^^^^^^^^^^^^^^^
  File "/root/tg_bot/Sharing/venv/lib/python3.11/site-packages/aiogram/bot/base.py", line 236, in request
    return await api.make_request(await self.get_session(), self.server, self.__token, method, data, files,
           ^^^^^^^^^^^^^^^^^^^^^^^^^^^^^^^^^^^^^^^^^^^^^^^^^^^^^^^^^^^^^^^^^^^^^^^^^^^^^^^^^^^^^^^^^^^^^^^^
  File "/root/tg_bot/Sharing/venv/lib/python3.11/site-packages/aiogram/bot/api.py", line 140, in make_request
    return check_result(method, response.content_type, response.status, await response.text())
           ^^^^^^^^^^^^^^^^^^^^^^^^^^^^^^^^^^^^^^^^^^^^^^^^^^^^^^^^^^^^^^^^^^^^^^^^^^^^^^^^^^^
  File "/root/tg_bot/Sharing/venv/lib/python3.11/site-packages/aiogram/bot/api.py", line 111, in check_result
    raise exceptions.RetryAfter(parameters.retry_after)
aiogram.utils.exceptions.RetryAfter: Flood control exceeded. Retry in 5 seconds.
2025-09-22 09:15:44,922 - ERROR - Task exception was never retrieved
future: <Task finished name='Task-16428' coro=<Dispatcher._process_polling_updates() done, defined at /root/tg_bot/Sharing/venv/lib/python3.11/site-packages/aiogram/dispatcher/dispatcher.py:407> exception=RetryAfter('Flood control exceeded. Retry in 3 seconds.')>
Traceback (most recent call last):
  File "/root/tg_bot/Sharing/venv/lib/python3.11/site-packages/aiogram/dispatcher/dispatcher.py", line 415, in _process_polling_updates
    for responses in itertools.chain.from_iterable(await self.process_updates(updates, fast)):
                                                   ^^^^^^^^^^^^^^^^^^^^^^^^^^^^^^^^^^^^^^^^^
  File "/root/tg_bot/Sharing/venv/lib/python3.11/site-packages/aiogram/dispatcher/dispatcher.py", line 235, in process_updates
    return await asyncio.gather(*tasks)
           ^^^^^^^^^^^^^^^^^^^^^^^^^^^^
  File "/root/tg_bot/Sharing/venv/lib/python3.11/site-packages/aiogram/dispatcher/handler.py", line 117, in notify
    response = await handler_obj.handler(*args, **partial_data)
               ^^^^^^^^^^^^^^^^^^^^^^^^^^^^^^^^^^^^^^^^^^^^^^^^
  File "/root/tg_bot/Sharing/venv/lib/python3.11/site-packages/aiogram/dispatcher/dispatcher.py", line 256, in process_update
    return await self.message_handlers.notify(update.message)
           ^^^^^^^^^^^^^^^^^^^^^^^^^^^^^^^^^^^^^^^^^^^^^^^^^^
  File "/root/tg_bot/Sharing/venv/lib/python3.11/site-packages/aiogram/dispatcher/handler.py", line 117, in notify
    response = await handler_obj.handler(*args, **partial_data)
               ^^^^^^^^^^^^^^^^^^^^^^^^^^^^^^^^^^^^^^^^^^^^^^^^
  File "/root/tg_bot/Sharing/handlers.py", line 102, in handle_photo_messages
    await process_scooter_text(message, message.caption)
  File "/root/tg_bot/Sharing/handlers.py", line 92, in process_scooter_text
    await message.reply("\n".join(response_parts), parse_mode="HTML")
  File "/root/tg_bot/Sharing/venv/lib/python3.11/site-packages/aiogram/types/message.py", line 1687, in reply
    return await self.bot.send_message(
           ^^^^^^^^^^^^^^^^^^^^^^^^^^^^
  File "/root/tg_bot/Sharing/venv/lib/python3.11/site-packages/aiogram/bot/bot.py", line 346, in send_message
    result = await self.request(api.Methods.SEND_MESSAGE, payload)
             ^^^^^^^^^^^^^^^^^^^^^^^^^^^^^^^^^^^^^^^^^^^^^^^^^^^^^
  File "/root/tg_bot/Sharing/venv/lib/python3.11/site-packages/aiogram/bot/base.py", line 236, in request
    return await api.make_request(await self.get_session(), self.server, self.__token, method, data, files,
           ^^^^^^^^^^^^^^^^^^^^^^^^^^^^^^^^^^^^^^^^^^^^^^^^^^^^^^^^^^^^^^^^^^^^^^^^^^^^^^^^^^^^^^^^^^^^^^^^
  File "/root/tg_bot/Sharing/venv/lib/python3.11/site-packages/aiogram/bot/api.py", line 140, in make_request
    return check_result(method, response.content_type, response.status, await response.text())
           ^^^^^^^^^^^^^^^^^^^^^^^^^^^^^^^^^^^^^^^^^^^^^^^^^^^^^^^^^^^^^^^^^^^^^^^^^^^^^^^^^^^
  File "/root/tg_bot/Sharing/venv/lib/python3.11/site-packages/aiogram/bot/api.py", line 111, in check_result
    raise exceptions.RetryAfter(parameters.retry_after)
aiogram.utils.exceptions.RetryAfter: Flood control exceeded. Retry in 3 seconds.
2025-09-24 06:37:38,874 - INFO - Bot: eom_master_inspector [@eom_master_inspectorbot]
2025-09-24 06:37:39,040 - WARNING - Updates were skipped successfully.
2025-09-24 06:37:39,290 - INFO - Start polling.
2025-09-27 21:56:56,407 - INFO - Bot: eom_master_inspector [@eom_master_inspectorbot]
2025-09-27 21:56:56,572 - WARNING - Updates were skipped successfully.
2025-09-27 21:56:56,981 - INFO - Start polling.
2025-09-29 10:00:12,528 - INFO - Bot: eom_master_inspector [@eom_master_inspectorbot]
2025-09-29 10:00:12,686 - WARNING - Updates were skipped successfully.
2025-09-29 10:00:13,041 - INFO - Start polling.
2025-10-01 02:33:23,037 - ERROR - Task exception was never retrieved
future: <Task finished name='Task-18006' coro=<Dispatcher._process_polling_updates() done, defined at /root/tg_bot/Sharing/venv/lib/python3.11/site-packages/aiogram/dispatcher/dispatcher.py:407> exception=CantParseEntities('Can\'t parse entities: unsupported start tag "начало" at byte offset 40')>
Traceback (most recent call last):
  File "/root/tg_bot/Sharing/venv/lib/python3.11/site-packages/aiogram/dispatcher/dispatcher.py", line 415, in _process_polling_updates
    for responses in itertools.chain.from_iterable(await self.process_updates(updates, fast)):
                                                   ^^^^^^^^^^^^^^^^^^^^^^^^^^^^^^^^^^^^^^^^^
  File "/root/tg_bot/Sharing/venv/lib/python3.11/site-packages/aiogram/dispatcher/dispatcher.py", line 235, in process_updates
    return await asyncio.gather(*tasks)
           ^^^^^^^^^^^^^^^^^^^^^^^^^^^^
  File "/root/tg_bot/Sharing/venv/lib/python3.11/site-packages/aiogram/dispatcher/handler.py", line 117, in notify
    response = await handler_obj.handler(*args, **partial_data)
               ^^^^^^^^^^^^^^^^^^^^^^^^^^^^^^^^^^^^^^^^^^^^^^^^
  File "/root/tg_bot/Sharing/venv/lib/python3.11/site-packages/aiogram/dispatcher/dispatcher.py", line 256, in process_update
    return await self.message_handlers.notify(update.message)
           ^^^^^^^^^^^^^^^^^^^^^^^^^^^^^^^^^^^^^^^^^^^^^^^^^^
  File "/root/tg_bot/Sharing/venv/lib/python3.11/site-packages/aiogram/dispatcher/handler.py", line 117, in notify
    response = await handler_obj.handler(*args, **partial_data)
               ^^^^^^^^^^^^^^^^^^^^^^^^^^^^^^^^^^^^^^^^^^^^^^^^
  File "/root/tg_bot/Sharing/handlers.py", line 228, in service_report_handler
    await message.reply(
  File "/root/tg_bot/Sharing/venv/lib/python3.11/site-packages/aiogram/types/message.py", line 1687, in reply
    return await self.bot.send_message(
           ^^^^^^^^^^^^^^^^^^^^^^^^^^^^
  File "/root/tg_bot/Sharing/venv/lib/python3.11/site-packages/aiogram/bot/bot.py", line 346, in send_message
    result = await self.request(api.Methods.SEND_MESSAGE, payload)
             ^^^^^^^^^^^^^^^^^^^^^^^^^^^^^^^^^^^^^^^^^^^^^^^^^^^^^
  File "/root/tg_bot/Sharing/venv/lib/python3.11/site-packages/aiogram/bot/base.py", line 236, in request
    return await api.make_request(await self.get_session(), self.server, self.__token, method, data, files,
           ^^^^^^^^^^^^^^^^^^^^^^^^^^^^^^^^^^^^^^^^^^^^^^^^^^^^^^^^^^^^^^^^^^^^^^^^^^^^^^^^^^^^^^^^^^^^^^^^
  File "/root/tg_bot/Sharing/venv/lib/python3.11/site-packages/aiogram/bot/api.py", line 140, in make_request
    return check_result(method, response.content_type, response.status, await response.text())
           ^^^^^^^^^^^^^^^^^^^^^^^^^^^^^^^^^^^^^^^^^^^^^^^^^^^^^^^^^^^^^^^^^^^^^^^^^^^^^^^^^^^
  File "/root/tg_bot/Sharing/venv/lib/python3.11/site-packages/aiogram/bot/api.py", line 115, in check_result
    exceptions.BadRequest.detect(description)
  File "/root/tg_bot/Sharing/venv/lib/python3.11/site-packages/aiogram/utils/exceptions.py", line 140, in detect
    raise err(cls.text or description)
aiogram.utils.exceptions.CantParseEntities: Can't parse entities: unsupported start tag "начало" at byte offset 40
2025-10-01 06:31:05,204 - INFO - Bot: eom_master_inspector [@eom_master_inspectorbot]
2025-10-01 06:31:05,380 - WARNING - Updates were skipped successfully.
2025-10-01 06:31:05,554 - INFO - Start polling.
2025-10-01 10:28:00,025 - ERROR - Cause exception while getting updates.
Traceback (most recent call last):
  File "/root/tg_bot/Sharing/venv/lib/python3.11/site-packages/aiogram/dispatcher/dispatcher.py", line 381, in start_polling
    updates = await self.bot.get_updates(
              ^^^^^^^^^^^^^^^^^^^^^^^^^^^
  File "/root/tg_bot/Sharing/venv/lib/python3.11/site-packages/aiogram/bot/bot.py", line 110, in get_updates
    result = await self.request(api.Methods.GET_UPDATES, payload)
             ^^^^^^^^^^^^^^^^^^^^^^^^^^^^^^^^^^^^^^^^^^^^^^^^^^^^
  File "/root/tg_bot/Sharing/venv/lib/python3.11/site-packages/aiogram/bot/base.py", line 236, in request
    return await api.make_request(await self.get_session(), self.server, self.__token, method, data, files,
           ^^^^^^^^^^^^^^^^^^^^^^^^^^^^^^^^^^^^^^^^^^^^^^^^^^^^^^^^^^^^^^^^^^^^^^^^^^^^^^^^^^^^^^^^^^^^^^^^
  File "/root/tg_bot/Sharing/venv/lib/python3.11/site-packages/aiogram/bot/api.py", line 139, in make_request
    async with session.post(url, data=req, **kwargs) as response:
  File "/root/tg_bot/Sharing/venv/lib/python3.11/site-packages/aiohttp/client.py", line 1167, in __aenter__
    self._resp = await self._coro
                 ^^^^^^^^^^^^^^^^
  File "/root/tg_bot/Sharing/venv/lib/python3.11/site-packages/aiohttp/client.py", line 586, in _request
    await resp.start(conn)
  File "/root/tg_bot/Sharing/venv/lib/python3.11/site-packages/aiohttp/client_reqrep.py", line 900, in start
    with self._timer:
  File "/root/tg_bot/Sharing/venv/lib/python3.11/site-packages/aiohttp/helpers.py", line 725, in __exit__
    raise asyncio.TimeoutError from None
TimeoutError
2025-10-01 10:30:19,449 - ERROR - Cause exception while getting updates.
Traceback (most recent call last):
  File "/root/tg_bot/Sharing/venv/lib/python3.11/site-packages/aiohttp/connector.py", line 980, in _wrap_create_connection
    return await self._loop.create_connection(*args, **kwargs)  # type: ignore[return-value]  # noqa
           ^^^^^^^^^^^^^^^^^^^^^^^^^^^^^^^^^^^^^^^^^^^^^^^^^^^
  File "/usr/lib/python3.11/asyncio/base_events.py", line 1086, in create_connection
    raise exceptions[0]
  File "/usr/lib/python3.11/asyncio/base_events.py", line 1070, in create_connection
    sock = await self._connect_sock(
           ^^^^^^^^^^^^^^^^^^^^^^^^^
  File "/usr/lib/python3.11/asyncio/base_events.py", line 974, in _connect_sock
    await self.sock_connect(sock, address)
  File "/usr/lib/python3.11/asyncio/selector_events.py", line 638, in sock_connect
    return await fut
           ^^^^^^^^^
  File "/usr/lib/python3.11/asyncio/selector_events.py", line 646, in _sock_connect
    sock.connect(address)
OSError: [Errno 101] Network is unreachable

The above exception was the direct cause of the following exception:

Traceback (most recent call last):
  File "/root/tg_bot/Sharing/venv/lib/python3.11/site-packages/aiogram/bot/api.py", line 139, in make_request
    async with session.post(url, data=req, **kwargs) as response:
  File "/root/tg_bot/Sharing/venv/lib/python3.11/site-packages/aiohttp/client.py", line 1167, in __aenter__
    self._resp = await self._coro
                 ^^^^^^^^^^^^^^^^
  File "/root/tg_bot/Sharing/venv/lib/python3.11/site-packages/aiohttp/client.py", line 562, in _request
    conn = await self._connector.connect(
           ^^^^^^^^^^^^^^^^^^^^^^^^^^^^^^
  File "/root/tg_bot/Sharing/venv/lib/python3.11/site-packages/aiohttp/connector.py", line 540, in connect
    proto = await self._create_connection(req, traces, timeout)
            ^^^^^^^^^^^^^^^^^^^^^^^^^^^^^^^^^^^^^^^^^^^^^^^^^^^
  File "/root/tg_bot/Sharing/venv/lib/python3.11/site-packages/aiohttp/connector.py", line 901, in _create_connection
    _, proto = await self._create_direct_connection(req, traces, timeout)
               ^^^^^^^^^^^^^^^^^^^^^^^^^^^^^^^^^^^^^^^^^^^^^^^^^^^^^^^^^^
  File "/root/tg_bot/Sharing/venv/lib/python3.11/site-packages/aiohttp/connector.py", line 1209, in _create_direct_connection
    raise last_exc
  File "/root/tg_bot/Sharing/venv/lib/python3.11/site-packages/aiohttp/connector.py", line 1178, in _create_direct_connection
    transp, proto = await self._wrap_create_connection(
                    ^^^^^^^^^^^^^^^^^^^^^^^^^^^^^^^^^^^
  File "/root/tg_bot/Sharing/venv/lib/python3.11/site-packages/aiohttp/connector.py", line 988, in _wrap_create_connection
    raise client_error(req.connection_key, exc) from exc
aiohttp.client_exceptions.ClientConnectorError: Cannot connect to host api.telegram.org:443 ssl:default [Network is unreachable]

During handling of the above exception, another exception occurred:

Traceback (most recent call last):
  File "/root/tg_bot/Sharing/venv/lib/python3.11/site-packages/aiogram/dispatcher/dispatcher.py", line 381, in start_polling
    updates = await self.bot.get_updates(
              ^^^^^^^^^^^^^^^^^^^^^^^^^^^
  File "/root/tg_bot/Sharing/venv/lib/python3.11/site-packages/aiogram/bot/bot.py", line 110, in get_updates
    result = await self.request(api.Methods.GET_UPDATES, payload)
             ^^^^^^^^^^^^^^^^^^^^^^^^^^^^^^^^^^^^^^^^^^^^^^^^^^^^
  File "/root/tg_bot/Sharing/venv/lib/python3.11/site-packages/aiogram/bot/base.py", line 236, in request
    return await api.make_request(await self.get_session(), self.server, self.__token, method, data, files,
           ^^^^^^^^^^^^^^^^^^^^^^^^^^^^^^^^^^^^^^^^^^^^^^^^^^^^^^^^^^^^^^^^^^^^^^^^^^^^^^^^^^^^^^^^^^^^^^^^
  File "/root/tg_bot/Sharing/venv/lib/python3.11/site-packages/aiogram/bot/api.py", line 142, in make_request
    raise exceptions.NetworkError(f"aiohttp client throws an error: {e.__class__.__name__}: {e}")
aiogram.utils.exceptions.NetworkError: Aiohttp client throws an error: ClientConnectorError: Cannot connect to host api.telegram.org:443 ssl:default [Network is unreachable]
2025-10-03 05:18:47,806 - ERROR - Task exception was never retrieved
future: <Task finished name='Task-15923' coro=<Dispatcher._process_polling_updates() done, defined at /root/tg_bot/Sharing/venv/lib/python3.11/site-packages/aiogram/dispatcher/dispatcher.py:407> exception=CantParseEntities('Can\'t parse entities: unsupported start tag "номер" at byte offset 43')>
Traceback (most recent call last):
  File "/root/tg_bot/Sharing/venv/lib/python3.11/site-packages/aiogram/dispatcher/dispatcher.py", line 415, in _process_polling_updates
    for responses in itertools.chain.from_iterable(await self.process_updates(updates, fast)):
                                                   ^^^^^^^^^^^^^^^^^^^^^^^^^^^^^^^^^^^^^^^^^
  File "/root/tg_bot/Sharing/venv/lib/python3.11/site-packages/aiogram/dispatcher/dispatcher.py", line 235, in process_updates
    return await asyncio.gather(*tasks)
           ^^^^^^^^^^^^^^^^^^^^^^^^^^^^
  File "/root/tg_bot/Sharing/venv/lib/python3.11/site-packages/aiogram/dispatcher/handler.py", line 117, in notify
    response = await handler_obj.handler(*args, **partial_data)
               ^^^^^^^^^^^^^^^^^^^^^^^^^^^^^^^^^^^^^^^^^^^^^^^^
  File "/root/tg_bot/Sharing/venv/lib/python3.11/site-packages/aiogram/dispatcher/dispatcher.py", line 256, in process_update
    return await self.message_handlers.notify(update.message)
           ^^^^^^^^^^^^^^^^^^^^^^^^^^^^^^^^^^^^^^^^^^^^^^^^^^
  File "/root/tg_bot/Sharing/venv/lib/python3.11/site-packages/aiogram/dispatcher/handler.py", line 117, in notify
    response = await handler_obj.handler(*args, **partial_data)
               ^^^^^^^^^^^^^^^^^^^^^^^^^^^^^^^^^^^^^^^^^^^^^^^^
  File "/root/tg_bot/Sharing/handlers.py", line 316, in find_scooter_handler
    await message.reply(
  File "/root/tg_bot/Sharing/venv/lib/python3.11/site-packages/aiogram/types/message.py", line 1687, in reply
    return await self.bot.send_message(
           ^^^^^^^^^^^^^^^^^^^^^^^^^^^^
  File "/root/tg_bot/Sharing/venv/lib/python3.11/site-packages/aiogram/bot/bot.py", line 346, in send_message
    result = await self.request(api.Methods.SEND_MESSAGE, payload)
             ^^^^^^^^^^^^^^^^^^^^^^^^^^^^^^^^^^^^^^^^^^^^^^^^^^^^^
  File "/root/tg_bot/Sharing/venv/lib/python3.11/site-packages/aiogram/bot/base.py", line 236, in request
    return await api.make_request(await self.get_session(), self.server, self.__token, method, data, files,
           ^^^^^^^^^^^^^^^^^^^^^^^^^^^^^^^^^^^^^^^^^^^^^^^^^^^^^^^^^^^^^^^^^^^^^^^^^^^^^^^^^^^^^^^^^^^^^^^^
  File "/root/tg_bot/Sharing/venv/lib/python3.11/site-packages/aiogram/bot/api.py", line 140, in make_request
    return check_result(method, response.content_type, response.status, await response.text())
           ^^^^^^^^^^^^^^^^^^^^^^^^^^^^^^^^^^^^^^^^^^^^^^^^^^^^^^^^^^^^^^^^^^^^^^^^^^^^^^^^^^^
  File "/root/tg_bot/Sharing/venv/lib/python3.11/site-packages/aiogram/bot/api.py", line 115, in check_result
    exceptions.BadRequest.detect(description)
  File "/root/tg_bot/Sharing/venv/lib/python3.11/site-packages/aiogram/utils/exceptions.py", line 140, in detect
    raise err(cls.text or description)
aiogram.utils.exceptions.CantParseEntities: Can't parse entities: unsupported start tag "номер" at byte offset 43
2025-10-06 15:36:36,497 - ERROR - Task exception was never retrieved
future: <Task finished name='Task-51336' coro=<Dispatcher._process_polling_updates() done, defined at /root/tg_bot/Sharing/venv/lib/python3.11/site-packages/aiogram/dispatcher/dispatcher.py:407> exception=CantParseEntities('Can\'t parse entities: unsupported start tag "номер" at byte offset 43')>
Traceback (most recent call last):
  File "/root/tg_bot/Sharing/venv/lib/python3.11/site-packages/aiogram/dispatcher/dispatcher.py", line 415, in _process_polling_updates
    for responses in itertools.chain.from_iterable(await self.process_updates(updates, fast)):
                                                   ^^^^^^^^^^^^^^^^^^^^^^^^^^^^^^^^^^^^^^^^^
  File "/root/tg_bot/Sharing/venv/lib/python3.11/site-packages/aiogram/dispatcher/dispatcher.py", line 235, in process_updates
    return await asyncio.gather(*tasks)
           ^^^^^^^^^^^^^^^^^^^^^^^^^^^^
  File "/root/tg_bot/Sharing/venv/lib/python3.11/site-packages/aiogram/dispatcher/handler.py", line 117, in notify
    response = await handler_obj.handler(*args, **partial_data)
               ^^^^^^^^^^^^^^^^^^^^^^^^^^^^^^^^^^^^^^^^^^^^^^^^
  File "/root/tg_bot/Sharing/venv/lib/python3.11/site-packages/aiogram/dispatcher/dispatcher.py", line 256, in process_update
    return await self.message_handlers.notify(update.message)
           ^^^^^^^^^^^^^^^^^^^^^^^^^^^^^^^^^^^^^^^^^^^^^^^^^^
  File "/root/tg_bot/Sharing/venv/lib/python3.11/site-packages/aiogram/dispatcher/handler.py", line 117, in notify
    response = await handler_obj.handler(*args, **partial_data)
               ^^^^^^^^^^^^^^^^^^^^^^^^^^^^^^^^^^^^^^^^^^^^^^^^
  File "/root/tg_bot/Sharing/handlers.py", line 316, in find_scooter_handler
    await message.reply(
  File "/root/tg_bot/Sharing/venv/lib/python3.11/site-packages/aiogram/types/message.py", line 1687, in reply
    return await self.bot.send_message(
           ^^^^^^^^^^^^^^^^^^^^^^^^^^^^
  File "/root/tg_bot/Sharing/venv/lib/python3.11/site-packages/aiogram/bot/bot.py", line 346, in send_message
    result = await self.request(api.Methods.SEND_MESSAGE, payload)
             ^^^^^^^^^^^^^^^^^^^^^^^^^^^^^^^^^^^^^^^^^^^^^^^^^^^^^
  File "/root/tg_bot/Sharing/venv/lib/python3.11/site-packages/aiogram/bot/base.py", line 236, in request
    return await api.make_request(await self.get_session(), self.server, self.__token, method, data, files,
           ^^^^^^^^^^^^^^^^^^^^^^^^^^^^^^^^^^^^^^^^^^^^^^^^^^^^^^^^^^^^^^^^^^^^^^^^^^^^^^^^^^^^^^^^^^^^^^^^
  File "/root/tg_bot/Sharing/venv/lib/python3.11/site-packages/aiogram/bot/api.py", line 140, in make_request
    return check_result(method, response.content_type, response.status, await response.text())
           ^^^^^^^^^^^^^^^^^^^^^^^^^^^^^^^^^^^^^^^^^^^^^^^^^^^^^^^^^^^^^^^^^^^^^^^^^^^^^^^^^^^
  File "/root/tg_bot/Sharing/venv/lib/python3.11/site-packages/aiogram/bot/api.py", line 115, in check_result
    exceptions.BadRequest.detect(description)
  File "/root/tg_bot/Sharing/venv/lib/python3.11/site-packages/aiogram/utils/exceptions.py", line 140, in detect
    raise err(cls.text or description)
aiogram.utils.exceptions.CantParseEntities: Can't parse entities: unsupported start tag "номер" at byte offset 43
2025-10-06 17:21:38,873 - ERROR - Cause exception while getting updates.
Traceback (most recent call last):
  File "/root/tg_bot/Sharing/venv/lib/python3.11/site-packages/aiohttp/connector.py", line 980, in _wrap_create_connection
    return await self._loop.create_connection(*args, **kwargs)  # type: ignore[return-value]  # noqa
           ^^^^^^^^^^^^^^^^^^^^^^^^^^^^^^^^^^^^^^^^^^^^^^^^^^^
  File "/usr/lib/python3.11/asyncio/base_events.py", line 1086, in create_connection
    raise exceptions[0]
  File "/usr/lib/python3.11/asyncio/base_events.py", line 1070, in create_connection
    sock = await self._connect_sock(
           ^^^^^^^^^^^^^^^^^^^^^^^^^
  File "/usr/lib/python3.11/asyncio/base_events.py", line 974, in _connect_sock
    await self.sock_connect(sock, address)
  File "/usr/lib/python3.11/asyncio/selector_events.py", line 638, in sock_connect
    return await fut
           ^^^^^^^^^
  File "/usr/lib/python3.11/asyncio/selector_events.py", line 646, in _sock_connect
    sock.connect(address)
OSError: [Errno 101] Network is unreachable

The above exception was the direct cause of the following exception:

Traceback (most recent call last):
  File "/root/tg_bot/Sharing/venv/lib/python3.11/site-packages/aiogram/bot/api.py", line 139, in make_request
    async with session.post(url, data=req, **kwargs) as response:
  File "/root/tg_bot/Sharing/venv/lib/python3.11/site-packages/aiohttp/client.py", line 1167, in __aenter__
    self._resp = await self._coro
                 ^^^^^^^^^^^^^^^^
  File "/root/tg_bot/Sharing/venv/lib/python3.11/site-packages/aiohttp/client.py", line 562, in _request
    conn = await self._connector.connect(
           ^^^^^^^^^^^^^^^^^^^^^^^^^^^^^^
  File "/root/tg_bot/Sharing/venv/lib/python3.11/site-packages/aiohttp/connector.py", line 540, in connect
    proto = await self._create_connection(req, traces, timeout)
            ^^^^^^^^^^^^^^^^^^^^^^^^^^^^^^^^^^^^^^^^^^^^^^^^^^^
  File "/root/tg_bot/Sharing/venv/lib/python3.11/site-packages/aiohttp/connector.py", line 901, in _create_connection
    _, proto = await self._create_direct_connection(req, traces, timeout)
               ^^^^^^^^^^^^^^^^^^^^^^^^^^^^^^^^^^^^^^^^^^^^^^^^^^^^^^^^^^
  File "/root/tg_bot/Sharing/venv/lib/python3.11/site-packages/aiohttp/connector.py", line 1209, in _create_direct_connection
    raise last_exc
  File "/root/tg_bot/Sharing/venv/lib/python3.11/site-packages/aiohttp/connector.py", line 1178, in _create_direct_connection
    transp, proto = await self._wrap_create_connection(
                    ^^^^^^^^^^^^^^^^^^^^^^^^^^^^^^^^^^^
  File "/root/tg_bot/Sharing/venv/lib/python3.11/site-packages/aiohttp/connector.py", line 988, in _wrap_create_connection
    raise client_error(req.connection_key, exc) from exc
aiohttp.client_exceptions.ClientConnectorError: Cannot connect to host api.telegram.org:443 ssl:default [Network is unreachable]

During handling of the above exception, another exception occurred:

Traceback (most recent call last):
  File "/root/tg_bot/Sharing/venv/lib/python3.11/site-packages/aiogram/dispatcher/dispatcher.py", line 381, in start_polling
    updates = await self.bot.get_updates(
              ^^^^^^^^^^^^^^^^^^^^^^^^^^^
  File "/root/tg_bot/Sharing/venv/lib/python3.11/site-packages/aiogram/bot/bot.py", line 110, in get_updates
    result = await self.request(api.Methods.GET_UPDATES, payload)
             ^^^^^^^^^^^^^^^^^^^^^^^^^^^^^^^^^^^^^^^^^^^^^^^^^^^^
  File "/root/tg_bot/Sharing/venv/lib/python3.11/site-packages/aiogram/bot/base.py", line 236, in request
    return await api.make_request(await self.get_session(), self.server, self.__token, method, data, files,
           ^^^^^^^^^^^^^^^^^^^^^^^^^^^^^^^^^^^^^^^^^^^^^^^^^^^^^^^^^^^^^^^^^^^^^^^^^^^^^^^^^^^^^^^^^^^^^^^^
  File "/root/tg_bot/Sharing/venv/lib/python3.11/site-packages/aiogram/bot/api.py", line 142, in make_request
    raise exceptions.NetworkError(f"aiohttp client throws an error: {e.__class__.__name__}: {e}")
aiogram.utils.exceptions.NetworkError: Aiohttp client throws an error: ClientConnectorError: Cannot connect to host api.telegram.org:443 ssl:default [Network is unreachable]
2025-10-06 17:23:58,137 - ERROR - Cause exception while getting updates.
Traceback (most recent call last):
  File "/root/tg_bot/Sharing/venv/lib/python3.11/site-packages/aiohttp/connector.py", line 980, in _wrap_create_connection
    return await self._loop.create_connection(*args, **kwargs)  # type: ignore[return-value]  # noqa
           ^^^^^^^^^^^^^^^^^^^^^^^^^^^^^^^^^^^^^^^^^^^^^^^^^^^
  File "/usr/lib/python3.11/asyncio/base_events.py", line 1086, in create_connection
    raise exceptions[0]
  File "/usr/lib/python3.11/asyncio/base_events.py", line 1070, in create_connection
    sock = await self._connect_sock(
           ^^^^^^^^^^^^^^^^^^^^^^^^^
  File "/usr/lib/python3.11/asyncio/base_events.py", line 974, in _connect_sock
    await self.sock_connect(sock, address)
  File "/usr/lib/python3.11/asyncio/selector_events.py", line 638, in sock_connect
    return await fut
           ^^^^^^^^^
  File "/usr/lib/python3.11/asyncio/selector_events.py", line 646, in _sock_connect
    sock.connect(address)
OSError: [Errno 101] Network is unreachable

The above exception was the direct cause of the following exception:

Traceback (most recent call last):
  File "/root/tg_bot/Sharing/venv/lib/python3.11/site-packages/aiogram/bot/api.py", line 139, in make_request
    async with session.post(url, data=req, **kwargs) as response:
  File "/root/tg_bot/Sharing/venv/lib/python3.11/site-packages/aiohttp/client.py", line 1167, in __aenter__
    self._resp = await self._coro
                 ^^^^^^^^^^^^^^^^
  File "/root/tg_bot/Sharing/venv/lib/python3.11/site-packages/aiohttp/client.py", line 562, in _request
    conn = await self._connector.connect(
           ^^^^^^^^^^^^^^^^^^^^^^^^^^^^^^
  File "/root/tg_bot/Sharing/venv/lib/python3.11/site-packages/aiohttp/connector.py", line 540, in connect
    proto = await self._create_connection(req, traces, timeout)
            ^^^^^^^^^^^^^^^^^^^^^^^^^^^^^^^^^^^^^^^^^^^^^^^^^^^
  File "/root/tg_bot/Sharing/venv/lib/python3.11/site-packages/aiohttp/connector.py", line 901, in _create_connection
    _, proto = await self._create_direct_connection(req, traces, timeout)
               ^^^^^^^^^^^^^^^^^^^^^^^^^^^^^^^^^^^^^^^^^^^^^^^^^^^^^^^^^^
  File "/root/tg_bot/Sharing/venv/lib/python3.11/site-packages/aiohttp/connector.py", line 1209, in _create_direct_connection
    raise last_exc
  File "/root/tg_bot/Sharing/venv/lib/python3.11/site-packages/aiohttp/connector.py", line 1178, in _create_direct_connection
    transp, proto = await self._wrap_create_connection(
                    ^^^^^^^^^^^^^^^^^^^^^^^^^^^^^^^^^^^
  File "/root/tg_bot/Sharing/venv/lib/python3.11/site-packages/aiohttp/connector.py", line 988, in _wrap_create_connection
    raise client_error(req.connection_key, exc) from exc
aiohttp.client_exceptions.ClientConnectorError: Cannot connect to host api.telegram.org:443 ssl:default [Network is unreachable]

During handling of the above exception, another exception occurred:

Traceback (most recent call last):
  File "/root/tg_bot/Sharing/venv/lib/python3.11/site-packages/aiogram/dispatcher/dispatcher.py", line 381, in start_polling
    updates = await self.bot.get_updates(
              ^^^^^^^^^^^^^^^^^^^^^^^^^^^
  File "/root/tg_bot/Sharing/venv/lib/python3.11/site-packages/aiogram/bot/bot.py", line 110, in get_updates
    result = await self.request(api.Methods.GET_UPDATES, payload)
             ^^^^^^^^^^^^^^^^^^^^^^^^^^^^^^^^^^^^^^^^^^^^^^^^^^^^
  File "/root/tg_bot/Sharing/venv/lib/python3.11/site-packages/aiogram/bot/base.py", line 236, in request
    return await api.make_request(await self.get_session(), self.server, self.__token, method, data, files,
           ^^^^^^^^^^^^^^^^^^^^^^^^^^^^^^^^^^^^^^^^^^^^^^^^^^^^^^^^^^^^^^^^^^^^^^^^^^^^^^^^^^^^^^^^^^^^^^^^
  File "/root/tg_bot/Sharing/venv/lib/python3.11/site-packages/aiogram/bot/api.py", line 142, in make_request
    raise exceptions.NetworkError(f"aiohttp client throws an error: {e.__class__.__name__}: {e}")
aiogram.utils.exceptions.NetworkError: Aiohttp client throws an error: ClientConnectorError: Cannot connect to host api.telegram.org:443 ssl:default [Network is unreachable]
2025-10-06 17:24:25,946 - ERROR - Task exception was never retrieved
future: <Task finished name='Task-52835' coro=<Dispatcher._process_polling_updates() done, defined at /root/tg_bot/Sharing/venv/lib/python3.11/site-packages/aiogram/dispatcher/dispatcher.py:407> exception=TimeoutError()>
Traceback (most recent call last):
  File "/root/tg_bot/Sharing/venv/lib/python3.11/site-packages/aiogram/dispatcher/dispatcher.py", line 415, in _process_polling_updates
    for responses in itertools.chain.from_iterable(await self.process_updates(updates, fast)):
                                                   ^^^^^^^^^^^^^^^^^^^^^^^^^^^^^^^^^^^^^^^^^
  File "/root/tg_bot/Sharing/venv/lib/python3.11/site-packages/aiogram/dispatcher/dispatcher.py", line 235, in process_updates
    return await asyncio.gather(*tasks)
           ^^^^^^^^^^^^^^^^^^^^^^^^^^^^
  File "/root/tg_bot/Sharing/venv/lib/python3.11/site-packages/aiogram/dispatcher/handler.py", line 117, in notify
    response = await handler_obj.handler(*args, **partial_data)
               ^^^^^^^^^^^^^^^^^^^^^^^^^^^^^^^^^^^^^^^^^^^^^^^^
  File "/root/tg_bot/Sharing/venv/lib/python3.11/site-packages/aiogram/dispatcher/dispatcher.py", line 256, in process_update
    return await self.message_handlers.notify(update.message)
           ^^^^^^^^^^^^^^^^^^^^^^^^^^^^^^^^^^^^^^^^^^^^^^^^^^
  File "/root/tg_bot/Sharing/venv/lib/python3.11/site-packages/aiogram/dispatcher/handler.py", line 117, in notify
    response = await handler_obj.handler(*args, **partial_data)
               ^^^^^^^^^^^^^^^^^^^^^^^^^^^^^^^^^^^^^^^^^^^^^^^^
  File "/root/tg_bot/Sharing/handlers.py", line 102, in handle_photo_messages
    await process_scooter_text(message, message.caption)
  File "/root/tg_bot/Sharing/handlers.py", line 92, in process_scooter_text
    await message.reply("\n".join(response_parts), parse_mode="HTML")
  File "/root/tg_bot/Sharing/venv/lib/python3.11/site-packages/aiogram/types/message.py", line 1687, in reply
    return await self.bot.send_message(
           ^^^^^^^^^^^^^^^^^^^^^^^^^^^^
  File "/root/tg_bot/Sharing/venv/lib/python3.11/site-packages/aiogram/bot/bot.py", line 346, in send_message
    result = await self.request(api.Methods.SEND_MESSAGE, payload)
             ^^^^^^^^^^^^^^^^^^^^^^^^^^^^^^^^^^^^^^^^^^^^^^^^^^^^^
  File "/root/tg_bot/Sharing/venv/lib/python3.11/site-packages/aiogram/bot/base.py", line 236, in request
    return await api.make_request(await self.get_session(), self.server, self.__token, method, data, files,
           ^^^^^^^^^^^^^^^^^^^^^^^^^^^^^^^^^^^^^^^^^^^^^^^^^^^^^^^^^^^^^^^^^^^^^^^^^^^^^^^^^^^^^^^^^^^^^^^^
  File "/root/tg_bot/Sharing/venv/lib/python3.11/site-packages/aiogram/bot/api.py", line 139, in make_request
    async with session.post(url, data=req, **kwargs) as response:
  File "/root/tg_bot/Sharing/venv/lib/python3.11/site-packages/aiohttp/client.py", line 1167, in __aenter__
    self._resp = await self._coro
                 ^^^^^^^^^^^^^^^^
  File "/root/tg_bot/Sharing/venv/lib/python3.11/site-packages/aiohttp/client.py", line 586, in _request
    await resp.start(conn)
  File "/root/tg_bot/Sharing/venv/lib/python3.11/site-packages/aiohttp/client_reqrep.py", line 900, in start
    with self._timer:
  File "/root/tg_bot/Sharing/venv/lib/python3.11/site-packages/aiohttp/helpers.py", line 725, in __exit__
    raise asyncio.TimeoutError from None
TimeoutError
2025-10-06 17:26:17,401 - ERROR - Cause exception while getting updates.
Traceback (most recent call last):
  File "/root/tg_bot/Sharing/venv/lib/python3.11/site-packages/aiohttp/connector.py", line 980, in _wrap_create_connection
    return await self._loop.create_connection(*args, **kwargs)  # type: ignore[return-value]  # noqa
           ^^^^^^^^^^^^^^^^^^^^^^^^^^^^^^^^^^^^^^^^^^^^^^^^^^^
  File "/usr/lib/python3.11/asyncio/base_events.py", line 1086, in create_connection
    raise exceptions[0]
  File "/usr/lib/python3.11/asyncio/base_events.py", line 1070, in create_connection
    sock = await self._connect_sock(
           ^^^^^^^^^^^^^^^^^^^^^^^^^
  File "/usr/lib/python3.11/asyncio/base_events.py", line 974, in _connect_sock
    await self.sock_connect(sock, address)
  File "/usr/lib/python3.11/asyncio/selector_events.py", line 638, in sock_connect
    return await fut
           ^^^^^^^^^
  File "/usr/lib/python3.11/asyncio/selector_events.py", line 646, in _sock_connect
    sock.connect(address)
OSError: [Errno 101] Network is unreachable

The above exception was the direct cause of the following exception:

Traceback (most recent call last):
  File "/root/tg_bot/Sharing/venv/lib/python3.11/site-packages/aiogram/bot/api.py", line 139, in make_request
    async with session.post(url, data=req, **kwargs) as response:
  File "/root/tg_bot/Sharing/venv/lib/python3.11/site-packages/aiohttp/client.py", line 1167, in __aenter__
    self._resp = await self._coro
                 ^^^^^^^^^^^^^^^^
  File "/root/tg_bot/Sharing/venv/lib/python3.11/site-packages/aiohttp/client.py", line 562, in _request
    conn = await self._connector.connect(
           ^^^^^^^^^^^^^^^^^^^^^^^^^^^^^^
  File "/root/tg_bot/Sharing/venv/lib/python3.11/site-packages/aiohttp/connector.py", line 540, in connect
    proto = await self._create_connection(req, traces, timeout)
            ^^^^^^^^^^^^^^^^^^^^^^^^^^^^^^^^^^^^^^^^^^^^^^^^^^^
  File "/root/tg_bot/Sharing/venv/lib/python3.11/site-packages/aiohttp/connector.py", line 901, in _create_connection
    _, proto = await self._create_direct_connection(req, traces, timeout)
               ^^^^^^^^^^^^^^^^^^^^^^^^^^^^^^^^^^^^^^^^^^^^^^^^^^^^^^^^^^
  File "/root/tg_bot/Sharing/venv/lib/python3.11/site-packages/aiohttp/connector.py", line 1209, in _create_direct_connection
    raise last_exc
  File "/root/tg_bot/Sharing/venv/lib/python3.11/site-packages/aiohttp/connector.py", line 1178, in _create_direct_connection
    transp, proto = await self._wrap_create_connection(
                    ^^^^^^^^^^^^^^^^^^^^^^^^^^^^^^^^^^^
  File "/root/tg_bot/Sharing/venv/lib/python3.11/site-packages/aiohttp/connector.py", line 988, in _wrap_create_connection
    raise client_error(req.connection_key, exc) from exc
aiohttp.client_exceptions.ClientConnectorError: Cannot connect to host api.telegram.org:443 ssl:default [Network is unreachable]

During handling of the above exception, another exception occurred:

Traceback (most recent call last):
  File "/root/tg_bot/Sharing/venv/lib/python3.11/site-packages/aiogram/dispatcher/dispatcher.py", line 381, in start_polling
    updates = await self.bot.get_updates(
              ^^^^^^^^^^^^^^^^^^^^^^^^^^^
  File "/root/tg_bot/Sharing/venv/lib/python3.11/site-packages/aiogram/bot/bot.py", line 110, in get_updates
    result = await self.request(api.Methods.GET_UPDATES, payload)
             ^^^^^^^^^^^^^^^^^^^^^^^^^^^^^^^^^^^^^^^^^^^^^^^^^^^^
  File "/root/tg_bot/Sharing/venv/lib/python3.11/site-packages/aiogram/bot/base.py", line 236, in request
    return await api.make_request(await self.get_session(), self.server, self.__token, method, data, files,
           ^^^^^^^^^^^^^^^^^^^^^^^^^^^^^^^^^^^^^^^^^^^^^^^^^^^^^^^^^^^^^^^^^^^^^^^^^^^^^^^^^^^^^^^^^^^^^^^^
  File "/root/tg_bot/Sharing/venv/lib/python3.11/site-packages/aiogram/bot/api.py", line 142, in make_request
    raise exceptions.NetworkError(f"aiohttp client throws an error: {e.__class__.__name__}: {e}")
aiogram.utils.exceptions.NetworkError: Aiohttp client throws an error: ClientConnectorError: Cannot connect to host api.telegram.org:443 ssl:default [Network is unreachable]
2025-10-06 17:28:36,665 - ERROR - Cause exception while getting updates.
Traceback (most recent call last):
  File "/root/tg_bot/Sharing/venv/lib/python3.11/site-packages/aiohttp/connector.py", line 980, in _wrap_create_connection
    return await self._loop.create_connection(*args, **kwargs)  # type: ignore[return-value]  # noqa
           ^^^^^^^^^^^^^^^^^^^^^^^^^^^^^^^^^^^^^^^^^^^^^^^^^^^
  File "/usr/lib/python3.11/asyncio/base_events.py", line 1086, in create_connection
    raise exceptions[0]
  File "/usr/lib/python3.11/asyncio/base_events.py", line 1070, in create_connection
    sock = await self._connect_sock(
           ^^^^^^^^^^^^^^^^^^^^^^^^^
  File "/usr/lib/python3.11/asyncio/base_events.py", line 974, in _connect_sock
    await self.sock_connect(sock, address)
  File "/usr/lib/python3.11/asyncio/selector_events.py", line 638, in sock_connect
    return await fut
           ^^^^^^^^^
  File "/usr/lib/python3.11/asyncio/selector_events.py", line 646, in _sock_connect
    sock.connect(address)
OSError: [Errno 101] Network is unreachable

The above exception was the direct cause of the following exception:

Traceback (most recent call last):
  File "/root/tg_bot/Sharing/venv/lib/python3.11/site-packages/aiogram/bot/api.py", line 139, in make_request
    async with session.post(url, data=req, **kwargs) as response:
  File "/root/tg_bot/Sharing/venv/lib/python3.11/site-packages/aiohttp/client.py", line 1167, in __aenter__
    self._resp = await self._coro
                 ^^^^^^^^^^^^^^^^
  File "/root/tg_bot/Sharing/venv/lib/python3.11/site-packages/aiohttp/client.py", line 562, in _request
    conn = await self._connector.connect(
           ^^^^^^^^^^^^^^^^^^^^^^^^^^^^^^
  File "/root/tg_bot/Sharing/venv/lib/python3.11/site-packages/aiohttp/connector.py", line 540, in connect
    proto = await self._create_connection(req, traces, timeout)
            ^^^^^^^^^^^^^^^^^^^^^^^^^^^^^^^^^^^^^^^^^^^^^^^^^^^
  File "/root/tg_bot/Sharing/venv/lib/python3.11/site-packages/aiohttp/connector.py", line 901, in _create_connection
    _, proto = await self._create_direct_connection(req, traces, timeout)
               ^^^^^^^^^^^^^^^^^^^^^^^^^^^^^^^^^^^^^^^^^^^^^^^^^^^^^^^^^^
  File "/root/tg_bot/Sharing/venv/lib/python3.11/site-packages/aiohttp/connector.py", line 1209, in _create_direct_connection
    raise last_exc
  File "/root/tg_bot/Sharing/venv/lib/python3.11/site-packages/aiohttp/connector.py", line 1178, in _create_direct_connection
    transp, proto = await self._wrap_create_connection(
                    ^^^^^^^^^^^^^^^^^^^^^^^^^^^^^^^^^^^
  File "/root/tg_bot/Sharing/venv/lib/python3.11/site-packages/aiohttp/connector.py", line 988, in _wrap_create_connection
    raise client_error(req.connection_key, exc) from exc
aiohttp.client_exceptions.ClientConnectorError: Cannot connect to host api.telegram.org:443 ssl:default [Network is unreachable]

During handling of the above exception, another exception occurred:

Traceback (most recent call last):
  File "/root/tg_bot/Sharing/venv/lib/python3.11/site-packages/aiogram/dispatcher/dispatcher.py", line 381, in start_polling
    updates = await self.bot.get_updates(
              ^^^^^^^^^^^^^^^^^^^^^^^^^^^
  File "/root/tg_bot/Sharing/venv/lib/python3.11/site-packages/aiogram/bot/bot.py", line 110, in get_updates
    result = await self.request(api.Methods.GET_UPDATES, payload)
             ^^^^^^^^^^^^^^^^^^^^^^^^^^^^^^^^^^^^^^^^^^^^^^^^^^^^
  File "/root/tg_bot/Sharing/venv/lib/python3.11/site-packages/aiogram/bot/base.py", line 236, in request
    return await api.make_request(await self.get_session(), self.server, self.__token, method, data, files,
           ^^^^^^^^^^^^^^^^^^^^^^^^^^^^^^^^^^^^^^^^^^^^^^^^^^^^^^^^^^^^^^^^^^^^^^^^^^^^^^^^^^^^^^^^^^^^^^^^
  File "/root/tg_bot/Sharing/venv/lib/python3.11/site-packages/aiogram/bot/api.py", line 142, in make_request
    raise exceptions.NetworkError(f"aiohttp client throws an error: {e.__class__.__name__}: {e}")
aiogram.utils.exceptions.NetworkError: Aiohttp client throws an error: ClientConnectorError: Cannot connect to host api.telegram.org:443 ssl:default [Network is unreachable]
2025-10-06 17:28:47,932 - ERROR - Task exception was never retrieved
future: <Task finished name='Task-52845' coro=<Dispatcher._process_polling_updates() done, defined at /root/tg_bot/Sharing/venv/lib/python3.11/site-packages/aiogram/dispatcher/dispatcher.py:407> exception=RetryAfter('Flood control exceeded. Retry in 5 seconds.')>
Traceback (most recent call last):
  File "/root/tg_bot/Sharing/venv/lib/python3.11/site-packages/aiogram/dispatcher/dispatcher.py", line 415, in _process_polling_updates
    for responses in itertools.chain.from_iterable(await self.process_updates(updates, fast)):
                                                   ^^^^^^^^^^^^^^^^^^^^^^^^^^^^^^^^^^^^^^^^^
  File "/root/tg_bot/Sharing/venv/lib/python3.11/site-packages/aiogram/dispatcher/dispatcher.py", line 235, in process_updates
    return await asyncio.gather(*tasks)
           ^^^^^^^^^^^^^^^^^^^^^^^^^^^^
  File "/root/tg_bot/Sharing/venv/lib/python3.11/site-packages/aiogram/dispatcher/handler.py", line 117, in notify
    response = await handler_obj.handler(*args, **partial_data)
               ^^^^^^^^^^^^^^^^^^^^^^^^^^^^^^^^^^^^^^^^^^^^^^^^
  File "/root/tg_bot/Sharing/venv/lib/python3.11/site-packages/aiogram/dispatcher/dispatcher.py", line 256, in process_update
    return await self.message_handlers.notify(update.message)
           ^^^^^^^^^^^^^^^^^^^^^^^^^^^^^^^^^^^^^^^^^^^^^^^^^^
  File "/root/tg_bot/Sharing/venv/lib/python3.11/site-packages/aiogram/dispatcher/handler.py", line 117, in notify
    response = await handler_obj.handler(*args, **partial_data)
               ^^^^^^^^^^^^^^^^^^^^^^^^^^^^^^^^^^^^^^^^^^^^^^^^
  File "/root/tg_bot/Sharing/handlers.py", line 102, in handle_photo_messages
    await process_scooter_text(message, message.caption)
  File "/root/tg_bot/Sharing/handlers.py", line 92, in process_scooter_text
    await message.reply("\n".join(response_parts), parse_mode="HTML")
  File "/root/tg_bot/Sharing/venv/lib/python3.11/site-packages/aiogram/types/message.py", line 1687, in reply
    return await self.bot.send_message(
           ^^^^^^^^^^^^^^^^^^^^^^^^^^^^
  File "/root/tg_bot/Sharing/venv/lib/python3.11/site-packages/aiogram/bot/bot.py", line 346, in send_message
    result = await self.request(api.Methods.SEND_MESSAGE, payload)
             ^^^^^^^^^^^^^^^^^^^^^^^^^^^^^^^^^^^^^^^^^^^^^^^^^^^^^
  File "/root/tg_bot/Sharing/venv/lib/python3.11/site-packages/aiogram/bot/base.py", line 236, in request
    return await api.make_request(await self.get_session(), self.server, self.__token, method, data, files,
           ^^^^^^^^^^^^^^^^^^^^^^^^^^^^^^^^^^^^^^^^^^^^^^^^^^^^^^^^^^^^^^^^^^^^^^^^^^^^^^^^^^^^^^^^^^^^^^^^
  File "/root/tg_bot/Sharing/venv/lib/python3.11/site-packages/aiogram/bot/api.py", line 140, in make_request
    return check_result(method, response.content_type, response.status, await response.text())
           ^^^^^^^^^^^^^^^^^^^^^^^^^^^^^^^^^^^^^^^^^^^^^^^^^^^^^^^^^^^^^^^^^^^^^^^^^^^^^^^^^^^
  File "/root/tg_bot/Sharing/venv/lib/python3.11/site-packages/aiogram/bot/api.py", line 111, in check_result
    raise exceptions.RetryAfter(parameters.retry_after)
aiogram.utils.exceptions.RetryAfter: Flood control exceeded. Retry in 5 seconds.
2025-10-09 12:59:54,884 - INFO - Bot: eom_master_inspector [@eom_master_inspectorbot]
2025-10-09 12:59:55,047 - WARNING - Updates were skipped successfully.
2025-10-09 12:59:55,131 - INFO - Adding job tentatively -- it will be properly scheduled when the scheduler starts
2025-10-09 12:59:55,132 - INFO - Adding job tentatively -- it will be properly scheduled when the scheduler starts
2025-10-09 12:59:55,132 - INFO - Added job "send_scheduled_report" to job store "default"
2025-10-09 12:59:55,132 - INFO - Added job "send_scheduled_report" to job store "default"
2025-10-09 12:59:55,132 - INFO - Scheduler started
2025-10-09 12:59:55,132 - INFO - Запущено задач в scheduler: ['morning_report', 'evening_report']
2025-10-09 12:59:55,132 - INFO - REPORT_CHAT_IDS: не загружены
2025-10-09 12:59:55,223 - INFO - Start polling.
2025-10-09 13:06:07,662 - INFO - Bot: eom_master_inspector [@eom_master_inspectorbot]
2025-10-09 13:06:07,822 - WARNING - Updates were skipped successfully.
2025-10-09 13:06:07,901 - INFO - Adding job tentatively -- it will be properly scheduled when the scheduler starts
2025-10-09 13:06:07,901 - INFO - Adding job tentatively -- it will be properly scheduled when the scheduler starts
2025-10-09 13:06:07,901 - INFO - Added job "send_scheduled_report" to job store "default"
2025-10-09 13:06:07,901 - INFO - Added job "send_scheduled_report" to job store "default"
2025-10-09 13:06:07,901 - INFO - Scheduler started
2025-10-09 13:06:07,901 - INFO - ✅ Планировщик запущен. Задачи: ['morning_report', 'evening_report']
2025-10-09 13:06:07,901 - INFO - 📤 REPORT_CHAT_IDS: {-1002549279303}
2025-10-09 13:06:08,036 - INFO - ✅ Тестовое сообщение отправлено в чат -1002549279303
2025-10-09 13:06:08,153 - INFO - ✅ Команды бота обновлены
2025-10-09 13:06:08,153 - INFO - Start polling.
2025-10-09 13:10:19,369 - INFO - Bot: eom_master_inspector [@eom_master_inspectorbot]
2025-10-09 13:10:19,527 - WARNING - Updates were skipped successfully.
2025-10-09 13:10:19,616 - INFO - Adding job tentatively -- it will be properly scheduled when the scheduler starts
2025-10-09 13:10:19,616 - INFO - Adding job tentatively -- it will be properly scheduled when the scheduler starts
2025-10-09 13:10:19,616 - INFO - Added job "send_scheduled_report" to job store "default"
2025-10-09 13:10:19,616 - INFO - Added job "send_scheduled_report" to job store "default"
2025-10-09 13:10:19,616 - INFO - Scheduler started
2025-10-09 13:10:19,616 - INFO - ✅ Планировщик запущен. Задачи: ['morning_report', 'evening_report']
2025-10-09 13:10:19,617 - INFO - 📤 REPORT_CHAT_IDS: {-1002549279303}
2025-10-09 13:10:19,703 - INFO - ✅ Команды бота обновлены
2025-10-09 13:10:19,703 - INFO - Start polling.
2025-10-09 14:04:45,004 - ERROR - Update {"update_id": 682969658, "message": {"message_id": 550, "from": {"id": 8272665697, "is_bot": false, "first_name": "evn", "username": "sse_evn", "language_code": "en"}, "chat": {"id": 8272665697, "first_name": "evn", "username": "sse_evn", "type": "private"}, "date": 1760000684, "text": "/service_report", "entities": [{"type": "bot_command", "offset": 0, "length": 15}]}} вызвал ошибку: Can't parse entities: unsupported start tag "начало" at byte offset 40
Traceback (most recent call last):
  File "/root/tg_bot/Sharing/venv/lib/python3.11/site-packages/aiogram/dispatcher/dispatcher.py", line 256, in process_update
    return await self.message_handlers.notify(update.message)
           ^^^^^^^^^^^^^^^^^^^^^^^^^^^^^^^^^^^^^^^^^^^^^^^^^^
  File "/root/tg_bot/Sharing/venv/lib/python3.11/site-packages/aiogram/dispatcher/handler.py", line 117, in notify
    response = await handler_obj.handler(*args, **partial_data)
               ^^^^^^^^^^^^^^^^^^^^^^^^^^^^^^^^^^^^^^^^^^^^^^^^
  File "/root/tg_bot/Sharing/handlers.py", line 228, in service_report_handler
    await message.reply(
  File "/root/tg_bot/Sharing/venv/lib/python3.11/site-packages/aiogram/types/message.py", line 1687, in reply
    return await self.bot.send_message(
           ^^^^^^^^^^^^^^^^^^^^^^^^^^^^
  File "/root/tg_bot/Sharing/venv/lib/python3.11/site-packages/aiogram/bot/bot.py", line 346, in send_message
    result = await self.request(api.Methods.SEND_MESSAGE, payload)
             ^^^^^^^^^^^^^^^^^^^^^^^^^^^^^^^^^^^^^^^^^^^^^^^^^^^^^
  File "/root/tg_bot/Sharing/venv/lib/python3.11/site-packages/aiogram/bot/base.py", line 236, in request
    return await api.make_request(await self.get_session(), self.server, self.__token, method, data, files,
           ^^^^^^^^^^^^^^^^^^^^^^^^^^^^^^^^^^^^^^^^^^^^^^^^^^^^^^^^^^^^^^^^^^^^^^^^^^^^^^^^^^^^^^^^^^^^^^^^
  File "/root/tg_bot/Sharing/venv/lib/python3.11/site-packages/aiogram/bot/api.py", line 140, in make_request
    return check_result(method, response.content_type, response.status, await response.text())
           ^^^^^^^^^^^^^^^^^^^^^^^^^^^^^^^^^^^^^^^^^^^^^^^^^^^^^^^^^^^^^^^^^^^^^^^^^^^^^^^^^^^
  File "/root/tg_bot/Sharing/venv/lib/python3.11/site-packages/aiogram/bot/api.py", line 115, in check_result
    exceptions.BadRequest.detect(description)
  File "/root/tg_bot/Sharing/venv/lib/python3.11/site-packages/aiogram/utils/exceptions.py", line 140, in detect
    raise err(cls.text or description)
aiogram.utils.exceptions.CantParseEntities: Can't parse entities: unsupported start tag "начало" at byte offset 40
2025-10-09 14:05:07,224 - ERROR - Update {"update_id": 682969661, "message": {"message_id": 551, "from": {"id": 7290788782, "is_bot": false, "first_name": "evn", "username": "sse_ev1n", "language_code": "en"}, "chat": {"id": 7290788782, "first_name": "evn", "username": "sse_ev1n", "type": "private"}, "date": 1760000707, "text": "/service_report", "entities": [{"type": "bot_command", "offset": 0, "length": 15}]}} вызвал ошибку: Can't parse entities: unsupported start tag "начало" at byte offset 40
Traceback (most recent call last):
  File "/root/tg_bot/Sharing/venv/lib/python3.11/site-packages/aiogram/dispatcher/dispatcher.py", line 256, in process_update
    return await self.message_handlers.notify(update.message)
           ^^^^^^^^^^^^^^^^^^^^^^^^^^^^^^^^^^^^^^^^^^^^^^^^^^
  File "/root/tg_bot/Sharing/venv/lib/python3.11/site-packages/aiogram/dispatcher/handler.py", line 117, in notify
    response = await handler_obj.handler(*args, **partial_data)
               ^^^^^^^^^^^^^^^^^^^^^^^^^^^^^^^^^^^^^^^^^^^^^^^^
  File "/root/tg_bot/Sharing/handlers.py", line 228, in service_report_handler
    await message.reply(
  File "/root/tg_bot/Sharing/venv/lib/python3.11/site-packages/aiogram/types/message.py", line 1687, in reply
    return await self.bot.send_message(
           ^^^^^^^^^^^^^^^^^^^^^^^^^^^^
  File "/root/tg_bot/Sharing/venv/lib/python3.11/site-packages/aiogram/bot/bot.py", line 346, in send_message
    result = await self.request(api.Methods.SEND_MESSAGE, payload)
             ^^^^^^^^^^^^^^^^^^^^^^^^^^^^^^^^^^^^^^^^^^^^^^^^^^^^^
  File "/root/tg_bot/Sharing/venv/lib/python3.11/site-packages/aiogram/bot/base.py", line 236, in request
    return await api.make_request(await self.get_session(), self.server, self.__token, method, data, files,
           ^^^^^^^^^^^^^^^^^^^^^^^^^^^^^^^^^^^^^^^^^^^^^^^^^^^^^^^^^^^^^^^^^^^^^^^^^^^^^^^^^^^^^^^^^^^^^^^^
  File "/root/tg_bot/Sharing/venv/lib/python3.11/site-packages/aiogram/bot/api.py", line 140, in make_request
    return check_result(method, response.content_type, response.status, await response.text())
           ^^^^^^^^^^^^^^^^^^^^^^^^^^^^^^^^^^^^^^^^^^^^^^^^^^^^^^^^^^^^^^^^^^^^^^^^^^^^^^^^^^^
  File "/root/tg_bot/Sharing/venv/lib/python3.11/site-packages/aiogram/bot/api.py", line 115, in check_result
    exceptions.BadRequest.detect(description)
  File "/root/tg_bot/Sharing/venv/lib/python3.11/site-packages/aiogram/utils/exceptions.py", line 140, in detect
    raise err(cls.text or description)
aiogram.utils.exceptions.CantParseEntities: Can't parse entities: unsupported start tag "начало" at byte offset 40
2025-10-09 14:06:08,175 - ERROR - Update {"update_id": 682969662, "message": {"message_id": 552, "from": {"id": 7290788782, "is_bot": false, "first_name": "evn", "username": "sse_ev1n", "language_code": "en"}, "chat": {"id": 7290788782, "first_name": "evn", "username": "sse_ev1n", "type": "private"}, "date": 1760000768, "text": "/service_report", "entities": [{"type": "bot_command", "offset": 0, "length": 15}]}} вызвал ошибку: Can't parse entities: unsupported start tag "начало" at byte offset 40
Traceback (most recent call last):
  File "/root/tg_bot/Sharing/venv/lib/python3.11/site-packages/aiogram/dispatcher/dispatcher.py", line 256, in process_update
    return await self.message_handlers.notify(update.message)
           ^^^^^^^^^^^^^^^^^^^^^^^^^^^^^^^^^^^^^^^^^^^^^^^^^^
  File "/root/tg_bot/Sharing/venv/lib/python3.11/site-packages/aiogram/dispatcher/handler.py", line 117, in notify
    response = await handler_obj.handler(*args, **partial_data)
               ^^^^^^^^^^^^^^^^^^^^^^^^^^^^^^^^^^^^^^^^^^^^^^^^
  File "/root/tg_bot/Sharing/handlers.py", line 228, in service_report_handler
    await message.reply(
  File "/root/tg_bot/Sharing/venv/lib/python3.11/site-packages/aiogram/types/message.py", line 1687, in reply
    return await self.bot.send_message(
           ^^^^^^^^^^^^^^^^^^^^^^^^^^^^
  File "/root/tg_bot/Sharing/venv/lib/python3.11/site-packages/aiogram/bot/bot.py", line 346, in send_message
    result = await self.request(api.Methods.SEND_MESSAGE, payload)
             ^^^^^^^^^^^^^^^^^^^^^^^^^^^^^^^^^^^^^^^^^^^^^^^^^^^^^
  File "/root/tg_bot/Sharing/venv/lib/python3.11/site-packages/aiogram/bot/base.py", line 236, in request
    return await api.make_request(await self.get_session(), self.server, self.__token, method, data, files,
           ^^^^^^^^^^^^^^^^^^^^^^^^^^^^^^^^^^^^^^^^^^^^^^^^^^^^^^^^^^^^^^^^^^^^^^^^^^^^^^^^^^^^^^^^^^^^^^^^
  File "/root/tg_bot/Sharing/venv/lib/python3.11/site-packages/aiogram/bot/api.py", line 140, in make_request
    return check_result(method, response.content_type, response.status, await response.text())
           ^^^^^^^^^^^^^^^^^^^^^^^^^^^^^^^^^^^^^^^^^^^^^^^^^^^^^^^^^^^^^^^^^^^^^^^^^^^^^^^^^^^
  File "/root/tg_bot/Sharing/venv/lib/python3.11/site-packages/aiogram/bot/api.py", line 115, in check_result
    exceptions.BadRequest.detect(description)
  File "/root/tg_bot/Sharing/venv/lib/python3.11/site-packages/aiogram/utils/exceptions.py", line 140, in detect
    raise err(cls.text or description)
aiogram.utils.exceptions.CantParseEntities: Can't parse entities: unsupported start tag "начало" at byte offset 40
2025-10-09 14:06:59,710 - ERROR - Update {"update_id": 682969664, "message": {"message_id": 555, "from": {"id": 7290788782, "is_bot": false, "first_name": "evn", "username": "sse_ev1n", "language_code": "en"}, "chat": {"id": 7290788782, "first_name": "evn", "username": "sse_ev1n", "type": "private"}, "date": 1760000819, "text": "/service_report 2025-08-01 2025-08-15\n@eom_master_inspectorbot", "entities": [{"type": "bot_command", "offset": 0, "length": 15}, {"type": "text_link", "offset": 38, "length": 24, "url": "https://t.me/eom_master_inspectorbot"}], "link_preview_options": {"url": "https://t.me/eom_master_inspectorbot"}}} вызвал ошибку: Can't parse entities: unsupported start tag "начало" at byte offset 40
Traceback (most recent call last):
  File "/root/tg_bot/Sharing/venv/lib/python3.11/site-packages/aiogram/dispatcher/dispatcher.py", line 256, in process_update
    return await self.message_handlers.notify(update.message)
           ^^^^^^^^^^^^^^^^^^^^^^^^^^^^^^^^^^^^^^^^^^^^^^^^^^
  File "/root/tg_bot/Sharing/venv/lib/python3.11/site-packages/aiogram/dispatcher/handler.py", line 117, in notify
    response = await handler_obj.handler(*args, **partial_data)
               ^^^^^^^^^^^^^^^^^^^^^^^^^^^^^^^^^^^^^^^^^^^^^^^^
  File "/root/tg_bot/Sharing/handlers.py", line 228, in service_report_handler
    await message.reply(
  File "/root/tg_bot/Sharing/venv/lib/python3.11/site-packages/aiogram/types/message.py", line 1687, in reply
    return await self.bot.send_message(
           ^^^^^^^^^^^^^^^^^^^^^^^^^^^^
  File "/root/tg_bot/Sharing/venv/lib/python3.11/site-packages/aiogram/bot/bot.py", line 346, in send_message
    result = await self.request(api.Methods.SEND_MESSAGE, payload)
             ^^^^^^^^^^^^^^^^^^^^^^^^^^^^^^^^^^^^^^^^^^^^^^^^^^^^^
  File "/root/tg_bot/Sharing/venv/lib/python3.11/site-packages/aiogram/bot/base.py", line 236, in request
    return await api.make_request(await self.get_session(), self.server, self.__token, method, data, files,
           ^^^^^^^^^^^^^^^^^^^^^^^^^^^^^^^^^^^^^^^^^^^^^^^^^^^^^^^^^^^^^^^^^^^^^^^^^^^^^^^^^^^^^^^^^^^^^^^^
  File "/root/tg_bot/Sharing/venv/lib/python3.11/site-packages/aiogram/bot/api.py", line 140, in make_request
    return check_result(method, response.content_type, response.status, await response.text())
           ^^^^^^^^^^^^^^^^^^^^^^^^^^^^^^^^^^^^^^^^^^^^^^^^^^^^^^^^^^^^^^^^^^^^^^^^^^^^^^^^^^^
  File "/root/tg_bot/Sharing/venv/lib/python3.11/site-packages/aiogram/bot/api.py", line 115, in check_result
    exceptions.BadRequest.detect(description)
  File "/root/tg_bot/Sharing/venv/lib/python3.11/site-packages/aiogram/utils/exceptions.py", line 140, in detect
    raise err(cls.text or description)
aiogram.utils.exceptions.CantParseEntities: Can't parse entities: unsupported start tag "начало" at byte offset 40
2025-10-09 15:00:00,005 - INFO - Running job "send_scheduled_report (trigger: cron[hour='15', minute='0'], next run at: 2025-10-10 15:00:00 +05)" (scheduled at 2025-10-09 15:00:00+05:00)
2025-10-09 15:00:00,911 - INFO - ✅ Excel-отчёт отправлен в -1002549279303
2025-10-09 15:00:00,911 - INFO - Job "send_scheduled_report (trigger: cron[hour='15', minute='0'], next run at: 2025-10-10 15:00:00 +05)" executed successfully
2025-10-09 15:09:16,382 - ERROR - Update {"update_id": 682969833, "message": {"message_id": 558, "from": {"id": 1428218177, "is_bot": false, "first_name": "Айс", "username": "Ais_latte7", "language_code": "ru"}, "chat": {"id": 1428218177, "first_name": "Айс", "username": "Ais_latte7", "type": "private"}, "date": 1760004556, "text": "/service_report", "entities": [{"type": "bot_command", "offset": 0, "length": 15}]}} вызвал ошибку: Can't parse entities: unsupported start tag "начало" at byte offset 40
Traceback (most recent call last):
  File "/root/tg_bot/Sharing/venv/lib/python3.11/site-packages/aiogram/dispatcher/dispatcher.py", line 256, in process_update
    return await self.message_handlers.notify(update.message)
           ^^^^^^^^^^^^^^^^^^^^^^^^^^^^^^^^^^^^^^^^^^^^^^^^^^
  File "/root/tg_bot/Sharing/venv/lib/python3.11/site-packages/aiogram/dispatcher/handler.py", line 117, in notify
    response = await handler_obj.handler(*args, **partial_data)
               ^^^^^^^^^^^^^^^^^^^^^^^^^^^^^^^^^^^^^^^^^^^^^^^^
  File "/root/tg_bot/Sharing/handlers.py", line 228, in service_report_handler
    await message.reply(
  File "/root/tg_bot/Sharing/venv/lib/python3.11/site-packages/aiogram/types/message.py", line 1687, in reply
    return await self.bot.send_message(
           ^^^^^^^^^^^^^^^^^^^^^^^^^^^^
  File "/root/tg_bot/Sharing/venv/lib/python3.11/site-packages/aiogram/bot/bot.py", line 346, in send_message
    result = await self.request(api.Methods.SEND_MESSAGE, payload)
             ^^^^^^^^^^^^^^^^^^^^^^^^^^^^^^^^^^^^^^^^^^^^^^^^^^^^^
  File "/root/tg_bot/Sharing/venv/lib/python3.11/site-packages/aiogram/bot/base.py", line 236, in request
    return await api.make_request(await self.get_session(), self.server, self.__token, method, data, files,
           ^^^^^^^^^^^^^^^^^^^^^^^^^^^^^^^^^^^^^^^^^^^^^^^^^^^^^^^^^^^^^^^^^^^^^^^^^^^^^^^^^^^^^^^^^^^^^^^^
  File "/root/tg_bot/Sharing/venv/lib/python3.11/site-packages/aiogram/bot/api.py", line 140, in make_request
    return check_result(method, response.content_type, response.status, await response.text())
           ^^^^^^^^^^^^^^^^^^^^^^^^^^^^^^^^^^^^^^^^^^^^^^^^^^^^^^^^^^^^^^^^^^^^^^^^^^^^^^^^^^^
  File "/root/tg_bot/Sharing/venv/lib/python3.11/site-packages/aiogram/bot/api.py", line 115, in check_result
    exceptions.BadRequest.detect(description)
  File "/root/tg_bot/Sharing/venv/lib/python3.11/site-packages/aiogram/utils/exceptions.py", line 140, in detect
    raise err(cls.text or description)
aiogram.utils.exceptions.CantParseEntities: Can't parse entities: unsupported start tag "начало" at byte offset 40
2025-10-09 16:28:00,337 - ERROR - Update {"update_id": 682970116, "message": {"message_id": 562, "from": {"id": 1428218177, "is_bot": false, "first_name": "Айс", "username": "Ais_latte7", "language_code": "ru"}, "chat": {"id": 1428218177, "first_name": "Айс", "username": "Ais_latte7", "type": "private"}, "date": 1760009280, "text": "/delete_scooter", "entities": [{"type": "bot_command", "offset": 0, "length": 15}]}} вызвал ошибку: Can't parse entities: unsupported start tag "номер" at byte offset 48
Traceback (most recent call last):
  File "/root/tg_bot/Sharing/venv/lib/python3.11/site-packages/aiogram/dispatcher/dispatcher.py", line 256, in process_update
    return await self.message_handlers.notify(update.message)
           ^^^^^^^^^^^^^^^^^^^^^^^^^^^^^^^^^^^^^^^^^^^^^^^^^^
  File "/root/tg_bot/Sharing/venv/lib/python3.11/site-packages/aiogram/dispatcher/handler.py", line 117, in notify
    response = await handler_obj.handler(*args, **partial_data)
               ^^^^^^^^^^^^^^^^^^^^^^^^^^^^^^^^^^^^^^^^^^^^^^^^
  File "/root/tg_bot/Sharing/handlers.py", line 366, in delete_scooter_handler
    await message.reply(
  File "/root/tg_bot/Sharing/venv/lib/python3.11/site-packages/aiogram/types/message.py", line 1687, in reply
    return await self.bot.send_message(
           ^^^^^^^^^^^^^^^^^^^^^^^^^^^^
  File "/root/tg_bot/Sharing/venv/lib/python3.11/site-packages/aiogram/bot/bot.py", line 346, in send_message
    result = await self.request(api.Methods.SEND_MESSAGE, payload)
             ^^^^^^^^^^^^^^^^^^^^^^^^^^^^^^^^^^^^^^^^^^^^^^^^^^^^^
  File "/root/tg_bot/Sharing/venv/lib/python3.11/site-packages/aiogram/bot/base.py", line 236, in request
    return await api.make_request(await self.get_session(), self.server, self.__token, method, data, files,
           ^^^^^^^^^^^^^^^^^^^^^^^^^^^^^^^^^^^^^^^^^^^^^^^^^^^^^^^^^^^^^^^^^^^^^^^^^^^^^^^^^^^^^^^^^^^^^^^^
  File "/root/tg_bot/Sharing/venv/lib/python3.11/site-packages/aiogram/bot/api.py", line 140, in make_request
    return check_result(method, response.content_type, response.status, await response.text())
           ^^^^^^^^^^^^^^^^^^^^^^^^^^^^^^^^^^^^^^^^^^^^^^^^^^^^^^^^^^^^^^^^^^^^^^^^^^^^^^^^^^^
  File "/root/tg_bot/Sharing/venv/lib/python3.11/site-packages/aiogram/bot/api.py", line 115, in check_result
    exceptions.BadRequest.detect(description)
  File "/root/tg_bot/Sharing/venv/lib/python3.11/site-packages/aiogram/utils/exceptions.py", line 140, in detect
    raise err(cls.text or description)
aiogram.utils.exceptions.CantParseEntities: Can't parse entities: unsupported start tag "номер" at byte offset 48
2025-10-09 23:00:00,004 - INFO - Running job "send_scheduled_report (trigger: cron[hour='23', minute='0'], next run at: 2025-10-10 23:00:00 +05)" (scheduled at 2025-10-09 23:00:00+05:00)
2025-10-09 23:00:00,969 - INFO - ✅ Excel-отчёт отправлен в -1002549279303
2025-10-09 23:00:00,969 - INFO - Job "send_scheduled_report (trigger: cron[hour='23', minute='0'], next run at: 2025-10-10 23:00:00 +05)" executed successfully
2025-10-10 15:00:00,008 - INFO - Running job "send_scheduled_report (trigger: cron[hour='15', minute='0'], next run at: 2025-10-11 15:00:00 +05)" (scheduled at 2025-10-10 15:00:00+05:00)
2025-10-10 15:00:00,823 - INFO - ✅ Excel-отчёт отправлен в -1002549279303
2025-10-10 15:00:00,823 - INFO - Job "send_scheduled_report (trigger: cron[hour='15', minute='0'], next run at: 2025-10-11 15:00:00 +05)" executed successfully
2025-10-10 23:00:00,004 - INFO - Running job "send_scheduled_report (trigger: cron[hour='23', minute='0'], next run at: 2025-10-11 23:00:00 +05)" (scheduled at 2025-10-10 23:00:00+05:00)
2025-10-10 23:00:01,030 - INFO - ✅ Excel-отчёт отправлен в -1002549279303
2025-10-10 23:00:01,031 - INFO - Job "send_scheduled_report (trigger: cron[hour='23', minute='0'], next run at: 2025-10-11 23:00:00 +05)" executed successfully
2025-10-11 13:53:49,137 - ERROR - Update {"update_id": 682975411, "message": {"message_id": 516, "from": {"id": 8272665697, "is_bot": false, "first_name": "evn", "username": "sse_evn", "language_code": "ru"}, "chat": {"id": -1002549279303, "title": "Отчет с 07:00 до 15:00 с 23:00", "type": "supergroup"}, "date": 1760172828, "text": "/find_scooter@eom_master_inspectorbot", "entities": [{"type": "bot_command", "offset": 0, "length": 37}]}} вызвал ошибку: Can't parse entities: unsupported start tag "номер" at byte offset 43
Traceback (most recent call last):
  File "/root/tg_bot/Sharing/venv/lib/python3.11/site-packages/aiogram/dispatcher/dispatcher.py", line 256, in process_update
    return await self.message_handlers.notify(update.message)
           ^^^^^^^^^^^^^^^^^^^^^^^^^^^^^^^^^^^^^^^^^^^^^^^^^^
  File "/root/tg_bot/Sharing/venv/lib/python3.11/site-packages/aiogram/dispatcher/handler.py", line 117, in notify
    response = await handler_obj.handler(*args, **partial_data)
               ^^^^^^^^^^^^^^^^^^^^^^^^^^^^^^^^^^^^^^^^^^^^^^^^
  File "/root/tg_bot/Sharing/handlers.py", line 316, in find_scooter_handler
    await message.reply(
  File "/root/tg_bot/Sharing/venv/lib/python3.11/site-packages/aiogram/types/message.py", line 1687, in reply
    return await self.bot.send_message(
           ^^^^^^^^^^^^^^^^^^^^^^^^^^^^
  File "/root/tg_bot/Sharing/venv/lib/python3.11/site-packages/aiogram/bot/bot.py", line 346, in send_message
    result = await self.request(api.Methods.SEND_MESSAGE, payload)
             ^^^^^^^^^^^^^^^^^^^^^^^^^^^^^^^^^^^^^^^^^^^^^^^^^^^^^
  File "/root/tg_bot/Sharing/venv/lib/python3.11/site-packages/aiogram/bot/base.py", line 236, in request
    return await api.make_request(await self.get_session(), self.server, self.__token, method, data, files,
           ^^^^^^^^^^^^^^^^^^^^^^^^^^^^^^^^^^^^^^^^^^^^^^^^^^^^^^^^^^^^^^^^^^^^^^^^^^^^^^^^^^^^^^^^^^^^^^^^
  File "/root/tg_bot/Sharing/venv/lib/python3.11/site-packages/aiogram/bot/api.py", line 140, in make_request
    return check_result(method, response.content_type, response.status, await response.text())
           ^^^^^^^^^^^^^^^^^^^^^^^^^^^^^^^^^^^^^^^^^^^^^^^^^^^^^^^^^^^^^^^^^^^^^^^^^^^^^^^^^^^
  File "/root/tg_bot/Sharing/venv/lib/python3.11/site-packages/aiogram/bot/api.py", line 115, in check_result
    exceptions.BadRequest.detect(description)
  File "/root/tg_bot/Sharing/venv/lib/python3.11/site-packages/aiogram/utils/exceptions.py", line 140, in detect
    raise err(cls.text or description)
aiogram.utils.exceptions.CantParseEntities: Can't parse entities: unsupported start tag "номер" at byte offset 43
2025-10-11 15:00:00,002 - INFO - Running job "send_scheduled_report (trigger: cron[hour='15', minute='0'], next run at: 2025-10-12 15:00:00 +05)" (scheduled at 2025-10-11 15:00:00+05:00)
2025-10-11 15:00:00,736 - INFO - ✅ Excel-отчёт отправлен в -1002549279303
2025-10-11 15:00:00,737 - INFO - Job "send_scheduled_report (trigger: cron[hour='15', minute='0'], next run at: 2025-10-12 15:00:00 +05)" executed successfully
2025-10-11 21:09:17,136 - INFO - Bot: eom_master_inspector [@eom_master_inspectorbot]
2025-10-11 21:09:17,383 - WARNING - Updates were skipped successfully.
2025-10-11 21:09:17,551 - INFO - Adding job tentatively -- it will be properly scheduled when the scheduler starts
2025-10-11 21:09:17,551 - INFO - Adding job tentatively -- it will be properly scheduled when the scheduler starts
2025-10-11 21:09:17,552 - INFO - Added job "send_scheduled_report" to job store "default"
2025-10-11 21:09:17,552 - INFO - Added job "send_scheduled_report" to job store "default"
2025-10-11 21:09:17,552 - INFO - Scheduler started
2025-10-11 21:09:17,552 - INFO - ✅ Планировщик запущен. Задачи: ['evening_report', 'morning_report']
2025-10-11 21:09:17,552 - INFO - 📤 REPORT_CHAT_IDS: {-1002549279303}
2025-10-11 21:09:17,735 - INFO - ✅ Команды бота обновлены
2025-10-11 21:09:17,735 - INFO - Start polling.
2025-10-11 21:09:35,025 - ERROR - Update {"update_id": 682976590, "message": {"message_id": 591, "from": {"id": 8272665697, "is_bot": false, "first_name": "evn", "username": "sse_evn", "language_code": "ru"}, "chat": {"id": 8272665697, "first_name": "evn", "username": "sse_evn", "type": "private"}, "date": 1760198974, "text": "/monthly_report", "entities": [{"type": "bot_command", "offset": 0, "length": 15}]}} вызвал ошибку: Can't parse entities: unsupported start tag "месяц" at byte offset 45
Traceback (most recent call last):
  File "/root/tg_bot/Sharing/venv/lib/python3.11/site-packages/aiogram/dispatcher/dispatcher.py", line 256, in process_update
    return await self.message_handlers.notify(update.message)
           ^^^^^^^^^^^^^^^^^^^^^^^^^^^^^^^^^^^^^^^^^^^^^^^^^^
  File "/root/tg_bot/Sharing/venv/lib/python3.11/site-packages/aiogram/dispatcher/handler.py", line 117, in notify
    response = await handler_obj.handler(*args, **partial_data)
               ^^^^^^^^^^^^^^^^^^^^^^^^^^^^^^^^^^^^^^^^^^^^^^^^
  File "/root/tg_bot/Sharing/handlers.py", line 428, in monthly_report_handler
    await message.reply(
  File "/root/tg_bot/Sharing/venv/lib/python3.11/site-packages/aiogram/types/message.py", line 1687, in reply
    return await self.bot.send_message(
           ^^^^^^^^^^^^^^^^^^^^^^^^^^^^
  File "/root/tg_bot/Sharing/venv/lib/python3.11/site-packages/aiogram/bot/bot.py", line 346, in send_message
    result = await self.request(api.Methods.SEND_MESSAGE, payload)
             ^^^^^^^^^^^^^^^^^^^^^^^^^^^^^^^^^^^^^^^^^^^^^^^^^^^^^
  File "/root/tg_bot/Sharing/venv/lib/python3.11/site-packages/aiogram/bot/base.py", line 236, in request
    return await api.make_request(await self.get_session(), self.server, self.__token, method, data, files,
           ^^^^^^^^^^^^^^^^^^^^^^^^^^^^^^^^^^^^^^^^^^^^^^^^^^^^^^^^^^^^^^^^^^^^^^^^^^^^^^^^^^^^^^^^^^^^^^^^
  File "/root/tg_bot/Sharing/venv/lib/python3.11/site-packages/aiogram/bot/api.py", line 140, in make_request
    return check_result(method, response.content_type, response.status, await response.text())
           ^^^^^^^^^^^^^^^^^^^^^^^^^^^^^^^^^^^^^^^^^^^^^^^^^^^^^^^^^^^^^^^^^^^^^^^^^^^^^^^^^^^
  File "/root/tg_bot/Sharing/venv/lib/python3.11/site-packages/aiogram/bot/api.py", line 115, in check_result
    exceptions.BadRequest.detect(description)
  File "/root/tg_bot/Sharing/venv/lib/python3.11/site-packages/aiogram/utils/exceptions.py", line 140, in detect
    raise err(cls.text or description)
aiogram.utils.exceptions.CantParseEntities: Can't parse entities: unsupported start tag "месяц" at byte offset 45
2025-10-11 21:14:22,029 - INFO - Bot: eom_master_inspector [@eom_master_inspectorbot]
2025-10-11 21:14:22,259 - WARNING - Updates were skipped successfully.
2025-10-11 21:14:22,351 - INFO - Adding job tentatively -- it will be properly scheduled when the scheduler starts
2025-10-11 21:14:22,352 - INFO - Adding job tentatively -- it will be properly scheduled when the scheduler starts
2025-10-11 21:14:22,352 - INFO - Added job "send_scheduled_report" to job store "default"
2025-10-11 21:14:22,352 - INFO - Added job "send_scheduled_report" to job store "default"
2025-10-11 21:14:22,352 - INFO - Scheduler started
2025-10-11 21:14:22,352 - INFO - ✅ Планировщик запущен. Задачи: ['evening_report', 'morning_report']
2025-10-11 21:14:22,352 - INFO - 📤 REPORT_CHAT_IDS: {-1002549279303}
2025-10-11 21:14:22,495 - INFO - ✅ Команды бота обновлены
2025-10-11 21:14:22,495 - INFO - Start polling.
2025-10-11 21:16:35,946 - INFO - Bot: eom_master_inspector [@eom_master_inspectorbot]
2025-10-11 21:16:36,110 - WARNING - Updates were skipped successfully.
2025-10-11 21:16:36,207 - INFO - Adding job tentatively -- it will be properly scheduled when the scheduler starts
2025-10-11 21:16:36,207 - INFO - Adding job tentatively -- it will be properly scheduled when the scheduler starts
2025-10-11 21:16:36,207 - INFO - Added job "send_scheduled_report" to job store "default"
2025-10-11 21:16:36,207 - INFO - Added job "send_scheduled_report" to job store "default"
2025-10-11 21:16:36,207 - INFO - Scheduler started
2025-10-11 21:16:36,207 - INFO - ✅ Планировщик запущен. Задачи: ['evening_report', 'morning_report']
2025-10-11 21:16:36,208 - INFO - 📤 REPORT_CHAT_IDS: {-1002549279303}
2025-10-11 21:16:36,537 - INFO - ✅ Команды бота обновлены
2025-10-11 21:16:36,537 - INFO - Start polling.
2025-10-11 23:00:00,001 - INFO - Running job "send_scheduled_report (trigger: cron[hour='23', minute='0'], next run at: 2025-10-12 23:00:00 +05)" (scheduled at 2025-10-11 23:00:00+05:00)
2025-10-11 23:00:01,215 - INFO - ✅ Excel-отчёт отправлен в -1002549279303
2025-10-11 23:00:01,215 - INFO - Job "send_scheduled_report (trigger: cron[hour='23', minute='0'], next run at: 2025-10-12 23:00:00 +05)" executed successfully
2025-10-12 15:00:00,009 - INFO - Running job "send_scheduled_report (trigger: cron[hour='15', minute='0'], next run at: 2025-10-13 15:00:00 +05)" (scheduled at 2025-10-12 15:00:00+05:00)
2025-10-12 15:00:00,779 - INFO - ✅ Excel-отчёт отправлен в -1002549279303
2025-10-12 15:00:00,779 - INFO - Job "send_scheduled_report (trigger: cron[hour='15', minute='0'], next run at: 2025-10-13 15:00:00 +05)" executed successfully
2025-10-12 23:00:00,012 - INFO - Running job "send_scheduled_report (trigger: cron[hour='23', minute='0'], next run at: 2025-10-13 23:00:00 +05)" (scheduled at 2025-10-12 23:00:00+05:00)
2025-10-12 23:00:01,001 - INFO - ✅ Excel-отчёт отправлен в -1002549279303
2025-10-12 23:00:01,002 - INFO - Job "send_scheduled_report (trigger: cron[hour='23', minute='0'], next run at: 2025-10-13 23:00:00 +05)" executed successfully
